[2025-04-02T02:23:02.568+0000] {local_task_job_runner.py:123} INFO - ::group::Pre task execution logs
[2025-04-02T02:23:02.606+0000] {taskinstance.py:2614} INFO - Dependencies all met for dep_context=non-requeueable deps ti=<TaskInstance: 1-clean_data_dag.delete_data_task scheduled__2025-04-01T01:00:00+00:00 [queued]>
[2025-04-02T02:23:02.619+0000] {taskinstance.py:2614} INFO - Dependencies all met for dep_context=requeueable deps ti=<TaskInstance: 1-clean_data_dag.delete_data_task scheduled__2025-04-01T01:00:00+00:00 [queued]>
[2025-04-02T02:23:02.619+0000] {taskinstance.py:2867} INFO - Starting attempt 1 of 1
[2025-04-02T02:23:02.641+0000] {taskinstance.py:2890} INFO - Executing <Task(PythonOperator): delete_data_task> on 2025-04-01 01:00:00+00:00
[2025-04-02T02:23:02.662+0000] {standard_task_runner.py:72} INFO - Started process 1212 to run task
[2025-04-02T02:23:02.684+0000] {standard_task_runner.py:104} INFO - Running: ['***', 'tasks', 'run', '1-clean_data_dag', 'delete_data_task', 'scheduled__2025-04-01T01:00:00+00:00', '--job-id', '13', '--raw', '--subdir', 'DAGS_FOLDER/Borrar_datos.py', '--cfg-path', '/tmp/tmpqzw7o9jn']
[2025-04-02T02:23:02.696+0000] {standard_task_runner.py:105} INFO - Job 13: Subtask delete_data_task
[2025-04-02T02:23:02.880+0000] {task_command.py:467} INFO - Running <TaskInstance: 1-clean_data_dag.delete_data_task scheduled__2025-04-01T01:00:00+00:00 [running]> on host 407915519a00
[2025-04-02T02:23:03.041+0000] {taskinstance.py:3134} INFO - Exporting env vars: AIRFLOW_CTX_DAG_OWNER='***' AIRFLOW_CTX_DAG_ID='1-clean_data_dag' AIRFLOW_CTX_TASK_ID='delete_data_task' AIRFLOW_CTX_EXECUTION_DATE='2025-04-01T01:00:00+00:00' AIRFLOW_CTX_TRY_NUMBER='1' AIRFLOW_CTX_DAG_RUN_ID='scheduled__2025-04-01T01:00:00+00:00'
[2025-04-02T02:23:03.044+0000] {taskinstance.py:732} INFO - ::endgroup::
[2025-04-02T02:23:03.068+0000] {crypto.py:82} WARNING - empty cryptography key - values will not be stored encrypted.
[2025-04-02T02:23:03.069+0000] {base.py:84} INFO - Retrieving connection 'postgres_default'
[2025-04-02T02:23:03.078+0000] {sql.py:542} INFO - Running statement: DELETE FROM covertype, parameters: None
[2025-04-02T02:23:03.325+0000] {sql.py:551} INFO - Rows affected: 104580
[2025-04-02T02:23:03.378+0000] {logging_mixin.py:190} INFO - Todas las filas han sido eliminadas de la tabla
[2025-04-02T02:23:03.379+0000] {python.py:240} INFO - Done. Returned value was: None
[2025-04-02T02:23:03.402+0000] {taskinstance.py:341} INFO - ::group::Post task execution logs
[2025-04-02T02:23:03.403+0000] {taskinstance.py:353} INFO - Marking task as SUCCESS. dag_id=1-clean_data_dag, task_id=delete_data_task, run_id=scheduled__2025-04-01T01:00:00+00:00, execution_date=20250401T010000, start_date=20250402T022302, end_date=20250402T022303
[2025-04-02T02:23:03.501+0000] {local_task_job_runner.py:266} INFO - Task exited with return code 0
[2025-04-02T02:23:03.533+0000] {taskinstance.py:3901} INFO - 0 downstream tasks scheduled from follow-on schedule check
[2025-04-02T02:23:03.534+0000] {local_task_job_runner.py:245} INFO - ::endgroup::
[2025-04-02T02:34:57.701+0000] {local_task_job_runner.py:123} INFO - ::group::Pre task execution logs
[2025-04-02T02:34:57.855+0000] {taskinstance.py:2614} INFO - Dependencies all met for dep_context=non-requeueable deps ti=<TaskInstance: 1-clean_data_dag.delete_data_task scheduled__2025-04-01T01:00:00+00:00 [queued]>
[2025-04-02T02:34:57.930+0000] {taskinstance.py:2614} INFO - Dependencies all met for dep_context=requeueable deps ti=<TaskInstance: 1-clean_data_dag.delete_data_task scheduled__2025-04-01T01:00:00+00:00 [queued]>
[2025-04-02T02:34:57.936+0000] {taskinstance.py:2867} INFO - Starting attempt 1 of 1
[2025-04-02T02:34:57.980+0000] {taskinstance.py:2890} INFO - Executing <Task(PythonOperator): delete_data_task> on 2025-04-01 01:00:00+00:00
[2025-04-02T02:34:58.011+0000] {standard_task_runner.py:72} INFO - Started process 133 to run task
[2025-04-02T02:34:58.039+0000] {standard_task_runner.py:104} INFO - Running: ['***', 'tasks', 'run', '1-clean_data_dag', 'delete_data_task', 'scheduled__2025-04-01T01:00:00+00:00', '--job-id', '3', '--raw', '--subdir', 'DAGS_FOLDER/Borrar_datos.py', '--cfg-path', '/tmp/tmpkoui54zy']
[2025-04-02T02:34:58.042+0000] {standard_task_runner.py:105} INFO - Job 3: Subtask delete_data_task
[2025-04-02T02:34:58.317+0000] {task_command.py:467} INFO - Running <TaskInstance: 1-clean_data_dag.delete_data_task scheduled__2025-04-01T01:00:00+00:00 [running]> on host 66352f2efff5
[2025-04-02T02:34:58.714+0000] {taskinstance.py:3134} INFO - Exporting env vars: AIRFLOW_CTX_DAG_OWNER='***' AIRFLOW_CTX_DAG_ID='1-clean_data_dag' AIRFLOW_CTX_TASK_ID='delete_data_task' AIRFLOW_CTX_EXECUTION_DATE='2025-04-01T01:00:00+00:00' AIRFLOW_CTX_TRY_NUMBER='1' AIRFLOW_CTX_DAG_RUN_ID='scheduled__2025-04-01T01:00:00+00:00'
[2025-04-02T02:34:58.720+0000] {taskinstance.py:732} INFO - ::endgroup::
[2025-04-02T02:34:58.858+0000] {crypto.py:82} WARNING - empty cryptography key - values will not be stored encrypted.
[2025-04-02T02:34:58.860+0000] {base.py:84} INFO - Retrieving connection 'postgres_default'
[2025-04-02T02:34:58.881+0000] {sql.py:542} INFO - Running statement: DELETE FROM covertype, parameters: None
[2025-04-02T02:34:58.891+0000] {taskinstance.py:3313} ERROR - Task failed with exception
Traceback (most recent call last):
  File "/home/airflow/.local/lib/python3.8/site-packages/airflow/models/taskinstance.py", line 768, in _execute_task
    result = _execute_callable(context=context, **execute_callable_kwargs)
  File "/home/airflow/.local/lib/python3.8/site-packages/airflow/models/taskinstance.py", line 734, in _execute_callable
    return ExecutionCallableRunner(
  File "/home/airflow/.local/lib/python3.8/site-packages/airflow/utils/operator_helpers.py", line 252, in run
    return self.func(*args, **kwargs)
  File "/home/airflow/.local/lib/python3.8/site-packages/airflow/models/baseoperator.py", line 424, in wrapper
    return func(self, *args, **kwargs)
  File "/home/airflow/.local/lib/python3.8/site-packages/airflow/operators/python.py", line 238, in execute
    return_value = self.execute_callable()
  File "/home/airflow/.local/lib/python3.8/site-packages/airflow/operators/python.py", line 256, in execute_callable
    return runner.run(*self.op_args, **self.op_kwargs)
  File "/home/airflow/.local/lib/python3.8/site-packages/airflow/utils/operator_helpers.py", line 252, in run
    return self.func(*args, **kwargs)
  File "/opt/airflow/dags/Borrar_datos.py", line 29, in delete_all_data
    postgres_hook.run(query)
  File "/home/airflow/.local/lib/python3.8/site-packages/airflow/providers/common/sql/hooks/sql.py", line 487, in run
    self._run_command(cur, sql_statement, parameters)
  File "/home/airflow/.local/lib/python3.8/site-packages/airflow/providers/common/sql/hooks/sql.py", line 547, in _run_command
    cur.execute(sql_statement)
psycopg2.errors.UndefinedTable: relation "covertype" does not exist
LINE 1: DELETE FROM covertype
                    ^

[2025-04-02T02:34:58.955+0000] {taskinstance.py:1226} INFO - Marking task as FAILED. dag_id=1-clean_data_dag, task_id=delete_data_task, run_id=scheduled__2025-04-01T01:00:00+00:00, execution_date=20250401T010000, start_date=20250402T023457, end_date=20250402T023458
[2025-04-02T02:34:59.122+0000] {taskinstance.py:341} INFO - ::group::Post task execution logs
[2025-04-02T02:34:59.129+0000] {standard_task_runner.py:124} ERROR - Failed to execute job 3 for task delete_data_task (relation "covertype" does not exist
LINE 1: DELETE FROM covertype
                    ^
; 133)
Traceback (most recent call last):
  File "/home/airflow/.local/lib/python3.8/site-packages/airflow/task/task_runner/standard_task_runner.py", line 117, in _start_by_fork
    ret = args.func(args, dag=self.dag)
  File "/home/airflow/.local/lib/python3.8/site-packages/airflow/cli/cli_config.py", line 49, in command
    return func(*args, **kwargs)
  File "/home/airflow/.local/lib/python3.8/site-packages/airflow/utils/cli.py", line 116, in wrapper
    return f(*args, **kwargs)
  File "/home/airflow/.local/lib/python3.8/site-packages/airflow/cli/commands/task_command.py", line 483, in task_run
    task_return_code = _run_task_by_selected_method(args, _dag, ti)
  File "/home/airflow/.local/lib/python3.8/site-packages/airflow/cli/commands/task_command.py", line 256, in _run_task_by_selected_method
    return _run_raw_task(args, ti)
  File "/home/airflow/.local/lib/python3.8/site-packages/airflow/cli/commands/task_command.py", line 341, in _run_raw_task
    return ti._run_raw_task(
  File "/home/airflow/.local/lib/python3.8/site-packages/airflow/utils/session.py", line 97, in wrapper
    return func(*args, session=session, **kwargs)
  File "/home/airflow/.local/lib/python3.8/site-packages/airflow/models/taskinstance.py", line 3006, in _run_raw_task
    return _run_raw_task(
  File "/home/airflow/.local/lib/python3.8/site-packages/airflow/models/taskinstance.py", line 274, in _run_raw_task
    TaskInstance._execute_task_with_callbacks(
  File "/home/airflow/.local/lib/python3.8/site-packages/airflow/models/taskinstance.py", line 3161, in _execute_task_with_callbacks
    result = self._execute_task(context, task_orig)
  File "/home/airflow/.local/lib/python3.8/site-packages/airflow/models/taskinstance.py", line 3185, in _execute_task
    return _execute_task(self, context, task_orig)
  File "/home/airflow/.local/lib/python3.8/site-packages/airflow/models/taskinstance.py", line 768, in _execute_task
    result = _execute_callable(context=context, **execute_callable_kwargs)
  File "/home/airflow/.local/lib/python3.8/site-packages/airflow/models/taskinstance.py", line 734, in _execute_callable
    return ExecutionCallableRunner(
  File "/home/airflow/.local/lib/python3.8/site-packages/airflow/utils/operator_helpers.py", line 252, in run
    return self.func(*args, **kwargs)
  File "/home/airflow/.local/lib/python3.8/site-packages/airflow/models/baseoperator.py", line 424, in wrapper
    return func(self, *args, **kwargs)
  File "/home/airflow/.local/lib/python3.8/site-packages/airflow/operators/python.py", line 238, in execute
    return_value = self.execute_callable()
  File "/home/airflow/.local/lib/python3.8/site-packages/airflow/operators/python.py", line 256, in execute_callable
    return runner.run(*self.op_args, **self.op_kwargs)
  File "/home/airflow/.local/lib/python3.8/site-packages/airflow/utils/operator_helpers.py", line 252, in run
    return self.func(*args, **kwargs)
  File "/opt/airflow/dags/Borrar_datos.py", line 29, in delete_all_data
    postgres_hook.run(query)
  File "/home/airflow/.local/lib/python3.8/site-packages/airflow/providers/common/sql/hooks/sql.py", line 487, in run
    self._run_command(cur, sql_statement, parameters)
  File "/home/airflow/.local/lib/python3.8/site-packages/airflow/providers/common/sql/hooks/sql.py", line 547, in _run_command
    cur.execute(sql_statement)
psycopg2.errors.UndefinedTable: relation "covertype" does not exist
LINE 1: DELETE FROM covertype
                    ^

[2025-04-02T02:34:59.198+0000] {local_task_job_runner.py:266} INFO - Task exited with return code 1
[2025-04-02T02:34:59.266+0000] {taskinstance.py:3901} INFO - 0 downstream tasks scheduled from follow-on schedule check
[2025-04-02T02:34:59.278+0000] {local_task_job_runner.py:245} INFO - ::endgroup::
[2025-04-02T22:13:02.341+0000] {local_task_job_runner.py:123} INFO - ::group::Pre task execution logs
[2025-04-02T22:13:02.402+0000] {taskinstance.py:2614} INFO - Dependencies all met for dep_context=non-requeueable deps ti=<TaskInstance: 1-clean_data_dag.delete_data_task scheduled__2025-04-01T01:00:00+00:00 [queued]>
[2025-04-02T22:13:02.426+0000] {taskinstance.py:2614} INFO - Dependencies all met for dep_context=requeueable deps ti=<TaskInstance: 1-clean_data_dag.delete_data_task scheduled__2025-04-01T01:00:00+00:00 [queued]>
[2025-04-02T22:13:02.426+0000] {taskinstance.py:2867} INFO - Starting attempt 1 of 1
[2025-04-02T22:13:02.471+0000] {taskinstance.py:2890} INFO - Executing <Task(PythonOperator): delete_data_task> on 2025-04-01 01:00:00+00:00
[2025-04-02T22:13:02.502+0000] {standard_task_runner.py:72} INFO - Started process 536 to run task
[2025-04-02T22:13:02.519+0000] {standard_task_runner.py:104} INFO - Running: ['***', 'tasks', 'run', '1-clean_data_dag', 'delete_data_task', 'scheduled__2025-04-01T01:00:00+00:00', '--job-id', '19', '--raw', '--subdir', 'DAGS_FOLDER/Borrar_datos.py', '--cfg-path', '/tmp/tmp_g_73tm0']
[2025-04-02T22:13:02.526+0000] {standard_task_runner.py:105} INFO - Job 19: Subtask delete_data_task
[2025-04-02T22:13:02.727+0000] {task_command.py:467} INFO - Running <TaskInstance: 1-clean_data_dag.delete_data_task scheduled__2025-04-01T01:00:00+00:00 [running]> on host 007bc2195d27
[2025-04-02T22:13:02.963+0000] {taskinstance.py:3134} INFO - Exporting env vars: AIRFLOW_CTX_DAG_OWNER='***' AIRFLOW_CTX_DAG_ID='1-clean_data_dag' AIRFLOW_CTX_TASK_ID='delete_data_task' AIRFLOW_CTX_EXECUTION_DATE='2025-04-01T01:00:00+00:00' AIRFLOW_CTX_TRY_NUMBER='1' AIRFLOW_CTX_DAG_RUN_ID='scheduled__2025-04-01T01:00:00+00:00'
[2025-04-02T22:13:02.964+0000] {taskinstance.py:732} INFO - ::endgroup::
[2025-04-02T22:13:03.052+0000] {crypto.py:82} WARNING - empty cryptography key - values will not be stored encrypted.
[2025-04-02T22:13:03.053+0000] {base.py:84} INFO - Retrieving connection 'postgres_default'
[2025-04-02T22:13:03.064+0000] {sql.py:542} INFO - Running statement: DELETE FROM covertype, parameters: None
[2025-04-02T22:13:03.211+0000] {sql.py:551} INFO - Rows affected: 52290
[2025-04-02T22:13:03.237+0000] {logging_mixin.py:190} INFO - Todas las filas han sido eliminadas de la tabla
[2025-04-02T22:13:03.237+0000] {python.py:240} INFO - Done. Returned value was: None
[2025-04-02T22:13:03.264+0000] {taskinstance.py:341} INFO - ::group::Post task execution logs
[2025-04-02T22:13:03.265+0000] {taskinstance.py:353} INFO - Marking task as SUCCESS. dag_id=1-clean_data_dag, task_id=delete_data_task, run_id=scheduled__2025-04-01T01:00:00+00:00, execution_date=20250401T010000, start_date=20250402T221302, end_date=20250402T221303
[2025-04-02T22:13:03.345+0000] {local_task_job_runner.py:266} INFO - Task exited with return code 0
[2025-04-02T22:13:03.384+0000] {taskinstance.py:3901} INFO - 0 downstream tasks scheduled from follow-on schedule check
[2025-04-02T22:13:03.387+0000] {local_task_job_runner.py:245} INFO - ::endgroup::
