[2025-03-27T02:51:40.447+0000] {taskinstance.py:1125} INFO - Dependencies all met for dep_context=non-requeueable deps ti=<TaskInstance: Cargar_data.create_table scheduled__2025-03-27T02:50:13.495819+00:00 [queued]>
[2025-03-27T02:51:40.736+0000] {taskinstance.py:1125} INFO - Dependencies all met for dep_context=requeueable deps ti=<TaskInstance: Cargar_data.create_table scheduled__2025-03-27T02:50:13.495819+00:00 [queued]>
[2025-03-27T02:51:40.738+0000] {taskinstance.py:1331} INFO - Starting attempt 2 of 2
[2025-03-27T02:51:42.435+0000] {taskinstance.py:1350} INFO - Executing <Task(MySqlOperator): create_table> on 2025-03-27 02:50:13.495819+00:00
[2025-03-27T02:51:42.623+0000] {standard_task_runner.py:57} INFO - Started process 323 to run task
[2025-03-27T02:51:42.722+0000] {standard_task_runner.py:84} INFO - Running: ['***', 'tasks', 'run', 'Cargar_data', 'create_table', 'scheduled__2025-03-27T02:50:13.495819+00:00', '--job-id', '67', '--raw', '--subdir', 'DAGS_FOLDER/Cargar_datos.py', '--cfg-path', '/tmp/tmph4r2h840']
[2025-03-27T02:51:42.745+0000] {standard_task_runner.py:85} INFO - Job 67: Subtask create_table
[2025-03-27T02:51:43.468+0000] {task_command.py:410} INFO - Running <TaskInstance: Cargar_data.create_table scheduled__2025-03-27T02:50:13.495819+00:00 [running]> on host da7934f86d61
[2025-03-27T02:51:48.842+0000] {taskinstance.py:1570} INFO - Exporting env vars: AIRFLOW_CTX_DAG_OWNER='***' AIRFLOW_CTX_DAG_ID='Cargar_data' AIRFLOW_CTX_TASK_ID='create_table' AIRFLOW_CTX_EXECUTION_DATE='2025-03-27T02:50:13.495819+00:00' AIRFLOW_CTX_TRY_NUMBER='2' AIRFLOW_CTX_DAG_RUN_ID='scheduled__2025-03-27T02:50:13.495819+00:00'
[2025-03-27T02:51:48.869+0000] {sql.py:262} INFO - Executing: 
 USE ***_db;
 CREATE TABLE IF NOT EXISTS covertype (
     id INT AUTO_INCREMENT PRIMARY KEY,
 'Elevation' INT NOT NULL, 
    'Aspect' INT NOT NULL, 
    'Slope' INT NOT NULL, 
    'Horizontal_Distance_To_Hydrology' INT NOT NULL,
    'Vertical_Distance_To_Hydrology' INT NOT NULL,
    'Horizontal_Distance_To_Roadways' INT NOT NULL,
    'Hillshade_9am' INT NOT NULL,
    'Hillshade_Noon' INT NOT NULL,
    'Hillshade_3pm' INT NOT NULL,
    'Horizontal_Distance_To_Fire_Points' INT NOT NULL, 
    'Wilderness_Area' INT NOT NULL VARCHAR(50),
    'Soil_Type' VARCHAR(50),
    'Cover_Type INT NOT NULL,'
 );
 
[2025-03-27T02:51:48.900+0000] {crypto.py:83} WARNING - empty cryptography key - values will not be stored encrypted.
[2025-03-27T02:51:48.936+0000] {base.py:73} INFO - Using connection ID 'mysql_default' for task execution.
[2025-03-27T02:51:49.536+0000] {base.py:73} INFO - Using connection ID 'mysql_default' for task execution.
[2025-03-27T02:51:49.615+0000] {sql.py:375} INFO - Running statement: 
 USE ***_db;
 CREATE TABLE IF NOT EXISTS covertype (
     id INT AUTO_INCREMENT PRIMARY KEY,
 'Elevation' INT NOT NULL, 
    'Aspect' INT NOT NULL, 
    'Slope' INT NOT NULL, 
    'Horizontal_Distance_To_Hydrology' INT NOT NULL,
    'Vertical_Distance_To_Hydrology' INT NOT NULL,
    'Horizontal_Distance_To_Roadways' INT NOT NULL,
    'Hillshade_9am' INT NOT NULL,
    'Hillshade_Noon' INT NOT NULL,
    'Hillshade_3pm' INT NOT NULL,
    'Horizontal_Distance_To_Fire_Points' INT NOT NULL, 
    'Wilderness_Area' INT NOT NULL VARCHAR(50),
    'Soil_Type' VARCHAR(50),
    'Cover_Type INT NOT NULL,'
 );
 , parameters: None
[2025-03-27T02:51:49.617+0000] {sql.py:384} INFO - Rows affected: 0
[2025-03-27T02:51:49.630+0000] {taskinstance.py:1847} ERROR - Task failed with exception
Traceback (most recent call last):
  File "/home/airflow/.local/lib/python3.7/site-packages/airflow/providers/common/sql/operators/sql.py", line 274, in execute
    **extra_kwargs,
  File "/home/airflow/.local/lib/python3.7/site-packages/airflow/providers/common/sql/hooks/sql.py", line 358, in run
    self.descriptions.append(cur.description)
  File "/usr/local/lib/python3.7/contextlib.py", line 298, in __exit__
    self.thing.close()
  File "/home/airflow/.local/lib/python3.7/site-packages/MySQLdb/cursors.py", line 83, in close
    while self.nextset():
  File "/home/airflow/.local/lib/python3.7/site-packages/MySQLdb/cursors.py", line 137, in nextset
    nr = db.next_result()
MySQLdb.ProgrammingError: (1064, "You have an error in your SQL syntax; check the manual that corresponds to your MySQL server version for the right syntax to use near ''Elevation' INT NOT NULL, \n    'Aspect' INT NOT NULL, \n    'Slope' INT NOT NULL,' at line 3")
[2025-03-27T02:51:49.703+0000] {taskinstance.py:1373} INFO - Marking task as FAILED. dag_id=Cargar_data, task_id=create_table, execution_date=20250327T025013, start_date=20250327T025140, end_date=20250327T025149
[2025-03-27T02:51:50.269+0000] {standard_task_runner.py:109} ERROR - Failed to execute job 67 for task create_table ((1064, "You have an error in your SQL syntax; check the manual that corresponds to your MySQL server version for the right syntax to use near ''Elevation' INT NOT NULL, \n    'Aspect' INT NOT NULL, \n    'Slope' INT NOT NULL,' at line 3"); 323)
[2025-03-27T02:51:50.452+0000] {local_task_job_runner.py:232} INFO - Task exited with return code 1
[2025-03-27T02:51:50.574+0000] {taskinstance.py:2674} INFO - 0 downstream tasks scheduled from follow-on schedule check
