[2025-03-09T03:19:55.288+0000] {taskinstance.py:1125} INFO - Dependencies all met for dep_context=non-requeueable deps ti=<TaskInstance: 4Entrenamiento_model.entrenar_modelo manual__2025-03-09T03:19:51.604278+00:00 [queued]>
[2025-03-09T03:19:55.296+0000] {taskinstance.py:1125} INFO - Dependencies all met for dep_context=requeueable deps ti=<TaskInstance: 4Entrenamiento_model.entrenar_modelo manual__2025-03-09T03:19:51.604278+00:00 [queued]>
[2025-03-09T03:19:55.297+0000] {taskinstance.py:1331} INFO - Starting attempt 1 of 1
[2025-03-09T03:19:55.307+0000] {taskinstance.py:1350} INFO - Executing <Task(PythonOperator): entrenar_modelo> on 2025-03-09 03:19:51.604278+00:00
[2025-03-09T03:19:55.311+0000] {standard_task_runner.py:57} INFO - Started process 329 to run task
[2025-03-09T03:19:55.315+0000] {standard_task_runner.py:84} INFO - Running: ['***', 'tasks', 'run', '4Entrenamiento_model', 'entrenar_modelo', 'manual__2025-03-09T03:19:51.604278+00:00', '--job-id', '15', '--raw', '--subdir', 'DAGS_FOLDER/Entrenamiento_mode.py', '--cfg-path', '/tmp/tmp2difa2nr']
[2025-03-09T03:19:55.317+0000] {standard_task_runner.py:85} INFO - Job 15: Subtask entrenar_modelo
[2025-03-09T03:19:55.365+0000] {task_command.py:410} INFO - Running <TaskInstance: 4Entrenamiento_model.entrenar_modelo manual__2025-03-09T03:19:51.604278+00:00 [running]> on host d79f96be65f0
[2025-03-09T03:19:55.450+0000] {taskinstance.py:1570} INFO - Exporting env vars: AIRFLOW_CTX_DAG_OWNER='***' AIRFLOW_CTX_DAG_ID='4Entrenamiento_model' AIRFLOW_CTX_TASK_ID='entrenar_modelo' AIRFLOW_CTX_EXECUTION_DATE='2025-03-09T03:19:51.604278+00:00' AIRFLOW_CTX_TRY_NUMBER='1' AIRFLOW_CTX_DAG_RUN_ID='manual__2025-03-09T03:19:51.604278+00:00'
[2025-03-09T03:19:55.478+0000] {taskinstance.py:1847} ERROR - Task failed with exception
Traceback (most recent call last):
  File "/home/airflow/.local/lib/python3.7/site-packages/pandas/core/indexes/base.py", line 3361, in get_loc
    return self._engine.get_loc(casted_key)
  File "pandas/_libs/index.pyx", line 76, in pandas._libs.index.IndexEngine.get_loc
  File "pandas/_libs/index.pyx", line 108, in pandas._libs.index.IndexEngine.get_loc
  File "pandas/_libs/hashtable_class_helper.pxi", line 5198, in pandas._libs.hashtable.PyObjectHashTable.get_item
  File "pandas/_libs/hashtable_class_helper.pxi", line 5206, in pandas._libs.hashtable.PyObjectHashTable.get_item
KeyError: 'id'

The above exception was the direct cause of the following exception:

Traceback (most recent call last):
  File "/home/airflow/.local/lib/python3.7/site-packages/sklearn/utils/__init__.py", line 433, in _get_column_indices
    col_idx = all_columns.get_loc(col)
  File "/home/airflow/.local/lib/python3.7/site-packages/pandas/core/indexes/base.py", line 3363, in get_loc
    raise KeyError(key) from err
KeyError: 'id'

The above exception was the direct cause of the following exception:

Traceback (most recent call last):
  File "/home/airflow/.local/lib/python3.7/site-packages/airflow/operators/python.py", line 181, in execute
    return_value = self.execute_callable()
  File "/home/airflow/.local/lib/python3.7/site-packages/airflow/operators/python.py", line 198, in execute_callable
    return self.python_callable(*self.op_args, **self.op_kwargs)
  File "/opt/airflow/dags/Entrenamiento_mode.py", line 120, in entrenar_modelo
    model.fit(X_train, y_train)
  File "/home/airflow/.local/lib/python3.7/site-packages/sklearn/pipeline.py", line 390, in fit
    Xt = self._fit(X, y, **fit_params_steps)
  File "/home/airflow/.local/lib/python3.7/site-packages/sklearn/pipeline.py", line 355, in _fit
    **fit_params_steps[name],
  File "/home/airflow/.local/lib/python3.7/site-packages/joblib/memory.py", line 353, in __call__
    return self.func(*args, **kwargs)
  File "/home/airflow/.local/lib/python3.7/site-packages/sklearn/pipeline.py", line 893, in _fit_transform_one
    res = transformer.fit_transform(X, y, **fit_params)
  File "/home/airflow/.local/lib/python3.7/site-packages/sklearn/compose/_column_transformer.py", line 672, in fit_transform
    self._validate_column_callables(X)
  File "/home/airflow/.local/lib/python3.7/site-packages/sklearn/compose/_column_transformer.py", line 352, in _validate_column_callables
    transformer_to_input_indices[name] = _get_column_indices(X, columns)
  File "/home/airflow/.local/lib/python3.7/site-packages/sklearn/utils/__init__.py", line 441, in _get_column_indices
    raise ValueError("A given column is not a column of the dataframe") from e
ValueError: A given column is not a column of the dataframe
[2025-03-09T03:19:55.486+0000] {taskinstance.py:1373} INFO - Marking task as FAILED. dag_id=4Entrenamiento_model, task_id=entrenar_modelo, execution_date=20250309T031951, start_date=20250309T031955, end_date=20250309T031955
[2025-03-09T03:19:55.498+0000] {standard_task_runner.py:109} ERROR - Failed to execute job 15 for task entrenar_modelo (A given column is not a column of the dataframe; 329)
[2025-03-09T03:19:55.527+0000] {local_task_job_runner.py:232} INFO - Task exited with return code 1
[2025-03-09T03:19:55.559+0000] {taskinstance.py:2674} INFO - 0 downstream tasks scheduled from follow-on schedule check
