[2025-04-01T05:24:22.311+0000] {local_task_job_runner.py:123} INFO - ::group::Pre task execution logs
[2025-04-01T05:24:22.342+0000] {taskinstance.py:2614} INFO - Dependencies all met for dep_context=non-requeueable deps ti=<TaskInstance: 4-Entrenamiento_model.entrenar_modelo scheduled__2025-03-31T00:00:00+00:00 [queued]>
[2025-04-01T05:24:22.354+0000] {taskinstance.py:2614} INFO - Dependencies all met for dep_context=requeueable deps ti=<TaskInstance: 4-Entrenamiento_model.entrenar_modelo scheduled__2025-03-31T00:00:00+00:00 [queued]>
[2025-04-01T05:24:22.355+0000] {taskinstance.py:2867} INFO - Starting attempt 1 of 2
[2025-04-01T05:24:22.380+0000] {taskinstance.py:2890} INFO - Executing <Task(PythonOperator): entrenar_modelo> on 2025-03-31 00:00:00+00:00
[2025-04-01T05:24:22.407+0000] {standard_task_runner.py:72} INFO - Started process 232 to run task
[2025-04-01T05:24:22.416+0000] {standard_task_runner.py:104} INFO - Running: ['***', 'tasks', 'run', '4-Entrenamiento_model', 'entrenar_modelo', 'scheduled__2025-03-31T00:00:00+00:00', '--job-id', '9', '--raw', '--subdir', 'DAGS_FOLDER/Entrenamiento_mode.py', '--cfg-path', '/tmp/tmp6oz5ftoa']
[2025-04-01T05:24:22.427+0000] {standard_task_runner.py:105} INFO - Job 9: Subtask entrenar_modelo
[2025-04-01T05:24:22.540+0000] {task_command.py:467} INFO - Running <TaskInstance: 4-Entrenamiento_model.entrenar_modelo scheduled__2025-03-31T00:00:00+00:00 [running]> on host 090d44c3d28c
[2025-04-01T05:24:22.685+0000] {taskinstance.py:3134} INFO - Exporting env vars: AIRFLOW_CTX_DAG_OWNER='***' AIRFLOW_CTX_DAG_ID='4-Entrenamiento_model' AIRFLOW_CTX_TASK_ID='entrenar_modelo' AIRFLOW_CTX_EXECUTION_DATE='2025-03-31T00:00:00+00:00' AIRFLOW_CTX_TRY_NUMBER='1' AIRFLOW_CTX_DAG_RUN_ID='scheduled__2025-03-31T00:00:00+00:00'
[2025-04-01T05:24:22.687+0000] {taskinstance.py:732} INFO - ::endgroup::
[2025-04-01T05:24:22.736+0000] {warnings.py:109} WARNING - /opt/***/dags/Entrenamiento_mode.py:64: UserWarning: pandas only supports SQLAlchemy connectable (engine/connection) or database string URI or sqlite3 DBAPI2 connection. Other DBAPI2 objects are not tested. Please consider using SQLAlchemy.
  df = pd.read_sql(query, conn)

[2025-04-01T05:24:25.425+0000] {logging_mixin.py:190} WARNING - 2025/04/01 05:24:25 INFO mlflow.tracking.fluent: Experiment with name 'mlflow_tracking_examples' does not exist. Creating a new experiment.
[2025-04-01T05:24:29.390+0000] {logging_mixin.py:190} WARNING - 2025/04/01 05:24:29 WARNING mlflow.utils.git_utils: Failed to import Git (the Git executable is probably not on your PATH), so Git SHA is not available. Error: Failed to initialize: Bad git executable.
The git executable must be specified in one of the following ways:
    - be included in your $PATH
    - be set via $GIT_PYTHON_GIT_EXECUTABLE
    - explicitly set via git.refresh(<full-path-to-git-executable>)

All git commands will error until this is rectified.

This initial message can be silenced or aggravated in the future by setting the
$GIT_PYTHON_REFRESH environment variable. Use one of the following values:
    - quiet|q|silence|s|silent|none|n|0: for no message or exception
    - warn|w|warning|log|l|1: for a warning message (logging level CRITICAL, displayed by default)
    - error|e|exception|raise|r|2: for a raised exception

Example:
    export GIT_PYTHON_REFRESH=quiet
[2025-04-01T05:24:30.734+0000] {logging_mixin.py:190} WARNING - 2025/04/01 05:24:30 WARNING mlflow.utils: Truncated the value of the key `estimator`. Truncated value: `Pipeline(steps=[('column_trans',
                 ColumnTransformer(remainder='passthrough',
                                   transformers=[('onehotencoder',
                                                  OneHotEncoder(handle_unknown='ignore'),
                                                  ['Wilderness_Area',
                                                   'Soil_Type'])])),
                ('scaler', StandardScaler(with_mean=False)),
                ('RandomForestClassifier', Rand...`
[2025-04-01T05:24:30.768+0000] {logging_and_warnings.py:72} WARNING - /home/***/.local/lib/python3.8/site-packages/joblib/parallel.py:1359: UserWarning: Loky-backed parallel loops cannot be called in a multiprocessing, setting n_jobs=1
  n_jobs = self._backend.configure(n_jobs=self.n_jobs, parallel=self,

[2025-04-01T05:25:35.711+0000] {font_manager.py:1547} INFO - generated new fontManager
[2025-04-01T05:25:40.569+0000] {credentials.py:1147} INFO - Found credentials in environment variables.
[2025-04-01T05:25:42.167+0000] {logging_mixin.py:190} WARNING - 2025/04/01 05:25:42 WARNING mlflow.utils.autologging_utils: MLflow autologging encountered a warning: "/home/***/.local/lib/python3.8/site-packages/mlflow/models/signature.py:137: UserWarning: Hint: Inferred schema contains integer column(s). Integer columns in Python cannot represent missing values. If your input data contains missing values at inference time, it will be encoded as floats and will cause a schema enforcement error. The best way to avoid this problem is to infer the model schema based on a realistic data sample (training dataset) that includes missing values. Alternatively, you can declare integer columns as doubles (float64) whenever these columns may have missing values. See `Handling Integers With Missing Values <https://www.mlflow.org/docs/latest/models.html#handling-integers-with-missing-values>`_ for more details."
[2025-04-01T05:26:01.901+0000] {logging_mixin.py:190} WARNING - Registered model 'modelo1' already exists. Creating a new version of this model...
[2025-04-01T05:26:01.995+0000] {logging_mixin.py:190} WARNING - 2025/04/01 05:26:01 INFO mlflow.tracking._model_registry.client: Waiting up to 300 seconds for model version to finish creation. Model name: modelo1, version 2
[2025-04-01T05:26:01.995+0000] {logging_mixin.py:190} WARNING - Created version '2' of model 'modelo1'.
[2025-04-01T05:26:10.869+0000] {logging_mixin.py:190} WARNING - 2025/04/01 05:26:10 INFO mlflow.sklearn.utils: Logging the 5 best runs, 3 runs will be omitted.
[2025-04-01T05:26:11.836+0000] {python.py:240} INFO - Done. Returned value was: 0
[2025-04-01T05:26:11.918+0000] {taskinstance.py:341} INFO - ::group::Post task execution logs
[2025-04-01T05:26:11.921+0000] {taskinstance.py:353} INFO - Marking task as SUCCESS. dag_id=4-Entrenamiento_model, task_id=entrenar_modelo, run_id=scheduled__2025-03-31T00:00:00+00:00, execution_date=20250331T000000, start_date=20250401T052422, end_date=20250401T052611
[2025-04-01T05:26:12.188+0000] {local_task_job_runner.py:266} INFO - Task exited with return code 0
[2025-04-01T05:26:12.243+0000] {taskinstance.py:3901} INFO - 0 downstream tasks scheduled from follow-on schedule check
[2025-04-01T05:26:12.247+0000] {local_task_job_runner.py:245} INFO - ::endgroup::
[2025-04-01T05:52:55.993+0000] {local_task_job_runner.py:123} INFO - ::group::Pre task execution logs
[2025-04-01T05:52:56.038+0000] {taskinstance.py:2614} INFO - Dependencies all met for dep_context=non-requeueable deps ti=<TaskInstance: 4-Entrenamiento_model.entrenar_modelo scheduled__2025-03-31T00:00:00+00:00 [queued]>
[2025-04-01T05:52:56.059+0000] {taskinstance.py:2614} INFO - Dependencies all met for dep_context=requeueable deps ti=<TaskInstance: 4-Entrenamiento_model.entrenar_modelo scheduled__2025-03-31T00:00:00+00:00 [queued]>
[2025-04-01T05:52:56.060+0000] {taskinstance.py:2867} INFO - Starting attempt 1 of 2
[2025-04-01T05:52:56.088+0000] {taskinstance.py:2890} INFO - Executing <Task(PythonOperator): entrenar_modelo> on 2025-03-31 00:00:00+00:00
[2025-04-01T05:52:56.129+0000] {standard_task_runner.py:72} INFO - Started process 176 to run task
[2025-04-01T05:52:56.160+0000] {standard_task_runner.py:104} INFO - Running: ['***', 'tasks', 'run', '4-Entrenamiento_model', 'entrenar_modelo', 'scheduled__2025-03-31T00:00:00+00:00', '--job-id', '6', '--raw', '--subdir', 'DAGS_FOLDER/Entrenamiento_mode.py', '--cfg-path', '/tmp/tmpjaldo34q']
[2025-04-01T05:52:56.168+0000] {standard_task_runner.py:105} INFO - Job 6: Subtask entrenar_modelo
[2025-04-01T05:52:56.327+0000] {task_command.py:467} INFO - Running <TaskInstance: 4-Entrenamiento_model.entrenar_modelo scheduled__2025-03-31T00:00:00+00:00 [running]> on host b7c6052ef868
[2025-04-01T05:52:56.649+0000] {taskinstance.py:3134} INFO - Exporting env vars: AIRFLOW_CTX_DAG_OWNER='***' AIRFLOW_CTX_DAG_ID='4-Entrenamiento_model' AIRFLOW_CTX_TASK_ID='entrenar_modelo' AIRFLOW_CTX_EXECUTION_DATE='2025-03-31T00:00:00+00:00' AIRFLOW_CTX_TRY_NUMBER='1' AIRFLOW_CTX_DAG_RUN_ID='scheduled__2025-03-31T00:00:00+00:00'
[2025-04-01T05:52:56.651+0000] {taskinstance.py:732} INFO - ::endgroup::
[2025-04-01T05:52:56.721+0000] {warnings.py:109} WARNING - /opt/***/dags/Entrenamiento_mode.py:64: UserWarning: pandas only supports SQLAlchemy connectable (engine/connection) or database string URI or sqlite3 DBAPI2 connection. Other DBAPI2 objects are not tested. Please consider using SQLAlchemy.
  df = pd.read_sql(query, conn)

[2025-04-01T05:52:56.879+0000] {logging_mixin.py:190} WARNING - 2025/04/01 05:52:56 INFO mlflow.tracking.fluent: Experiment with name 'mlflow_tracking_examples' does not exist. Creating a new experiment.
[2025-04-01T05:52:59.496+0000] {logging_mixin.py:190} WARNING - 2025/04/01 05:52:59 WARNING mlflow.utils.git_utils: Failed to import Git (the Git executable is probably not on your PATH), so Git SHA is not available. Error: Failed to initialize: Bad git executable.
The git executable must be specified in one of the following ways:
    - be included in your $PATH
    - be set via $GIT_PYTHON_GIT_EXECUTABLE
    - explicitly set via git.refresh(<full-path-to-git-executable>)

All git commands will error until this is rectified.

This initial message can be silenced or aggravated in the future by setting the
$GIT_PYTHON_REFRESH environment variable. Use one of the following values:
    - quiet|q|silence|s|silent|none|n|0: for no message or exception
    - warn|w|warning|log|l|1: for a warning message (logging level CRITICAL, displayed by default)
    - error|e|exception|raise|r|2: for a raised exception

Example:
    export GIT_PYTHON_REFRESH=quiet
[2025-04-01T05:52:59.575+0000] {logging_mixin.py:190} WARNING - 2025/04/01 05:52:59 WARNING mlflow.utils: Truncated the value of the key `estimator`. Truncated value: `Pipeline(steps=[('column_trans',
                 ColumnTransformer(remainder='passthrough',
                                   transformers=[('onehotencoder',
                                                  OneHotEncoder(handle_unknown='ignore'),
                                                  ['Wilderness_Area',
                                                   'Soil_Type'])])),
                ('scaler', StandardScaler(with_mean=False)),
                ('RandomForestClassifier', Rand...`
[2025-04-01T05:52:59.585+0000] {logging_and_warnings.py:72} WARNING - /home/***/.local/lib/python3.8/site-packages/joblib/parallel.py:1359: UserWarning: Loky-backed parallel loops cannot be called in a multiprocessing, setting n_jobs=1
  n_jobs = self._backend.configure(n_jobs=self.n_jobs, parallel=self,

[2025-04-01T05:53:03.097+0000] {font_manager.py:1547} INFO - generated new fontManager
[2025-04-01T05:53:05.690+0000] {credentials.py:1147} INFO - Found credentials in environment variables.
[2025-04-01T05:53:07.170+0000] {logging_mixin.py:190} WARNING - 2025/04/01 05:53:07 WARNING mlflow.utils.autologging_utils: MLflow autologging encountered a warning: "/home/***/.local/lib/python3.8/site-packages/mlflow/models/signature.py:137: UserWarning: Hint: Inferred schema contains integer column(s). Integer columns in Python cannot represent missing values. If your input data contains missing values at inference time, it will be encoded as floats and will cause a schema enforcement error. The best way to avoid this problem is to infer the model schema based on a realistic data sample (training dataset) that includes missing values. Alternatively, you can declare integer columns as doubles (float64) whenever these columns may have missing values. See `Handling Integers With Missing Values <https://www.mlflow.org/docs/latest/models.html#handling-integers-with-missing-values>`_ for more details."
[2025-04-01T05:53:18.351+0000] {logging_mixin.py:190} WARNING - Successfully registered model 'modelo1'.
[2025-04-01T05:53:18.681+0000] {logging_mixin.py:190} WARNING - 2025/04/01 05:53:18 INFO mlflow.tracking._model_registry.client: Waiting up to 300 seconds for model version to finish creation. Model name: modelo1, version 1
[2025-04-01T05:53:18.685+0000] {logging_mixin.py:190} WARNING - Created version '1' of model 'modelo1'.
[2025-04-01T05:53:24.274+0000] {logging_mixin.py:190} WARNING - 2025/04/01 05:53:24 INFO mlflow.sklearn.utils: Logging the 5 best runs, 3 runs will be omitted.
[2025-04-01T05:53:25.159+0000] {python.py:240} INFO - Done. Returned value was: 0
[2025-04-01T05:53:25.224+0000] {taskinstance.py:341} INFO - ::group::Post task execution logs
[2025-04-01T05:53:25.225+0000] {taskinstance.py:353} INFO - Marking task as SUCCESS. dag_id=4-Entrenamiento_model, task_id=entrenar_modelo, run_id=scheduled__2025-03-31T00:00:00+00:00, execution_date=20250331T000000, start_date=20250401T055256, end_date=20250401T055325
[2025-04-01T05:53:25.406+0000] {local_task_job_runner.py:266} INFO - Task exited with return code 0
[2025-04-01T05:53:25.441+0000] {taskinstance.py:3901} INFO - 0 downstream tasks scheduled from follow-on schedule check
[2025-04-01T05:53:25.444+0000] {local_task_job_runner.py:245} INFO - ::endgroup::
[2025-04-01T06:23:08.225+0000] {local_task_job_runner.py:123} INFO - ::group::Pre task execution logs
[2025-04-01T06:23:08.297+0000] {taskinstance.py:2614} INFO - Dependencies all met for dep_context=non-requeueable deps ti=<TaskInstance: 4-Entrenamiento_model.entrenar_modelo scheduled__2025-03-31T00:00:00+00:00 [queued]>
[2025-04-01T06:23:08.317+0000] {taskinstance.py:2614} INFO - Dependencies all met for dep_context=requeueable deps ti=<TaskInstance: 4-Entrenamiento_model.entrenar_modelo scheduled__2025-03-31T00:00:00+00:00 [queued]>
[2025-04-01T06:23:08.318+0000] {taskinstance.py:2867} INFO - Starting attempt 1 of 2
[2025-04-01T06:23:08.344+0000] {taskinstance.py:2890} INFO - Executing <Task(PythonOperator): entrenar_modelo> on 2025-03-31 00:00:00+00:00
[2025-04-01T06:23:08.376+0000] {standard_task_runner.py:72} INFO - Started process 306 to run task
[2025-04-01T06:23:08.396+0000] {standard_task_runner.py:104} INFO - Running: ['***', 'tasks', 'run', '4-Entrenamiento_model', 'entrenar_modelo', 'scheduled__2025-03-31T00:00:00+00:00', '--job-id', '6', '--raw', '--subdir', 'DAGS_FOLDER/Entrenamiento_mode.py', '--cfg-path', '/tmp/tmpl7qjukd4']
[2025-04-01T06:23:08.409+0000] {standard_task_runner.py:105} INFO - Job 6: Subtask entrenar_modelo
[2025-04-01T06:23:08.593+0000] {task_command.py:467} INFO - Running <TaskInstance: 4-Entrenamiento_model.entrenar_modelo scheduled__2025-03-31T00:00:00+00:00 [running]> on host ed472e138aea
[2025-04-01T06:23:08.799+0000] {taskinstance.py:3134} INFO - Exporting env vars: AIRFLOW_CTX_DAG_OWNER='***' AIRFLOW_CTX_DAG_ID='4-Entrenamiento_model' AIRFLOW_CTX_TASK_ID='entrenar_modelo' AIRFLOW_CTX_EXECUTION_DATE='2025-03-31T00:00:00+00:00' AIRFLOW_CTX_TRY_NUMBER='1' AIRFLOW_CTX_DAG_RUN_ID='scheduled__2025-03-31T00:00:00+00:00'
[2025-04-01T06:23:08.801+0000] {taskinstance.py:732} INFO - ::endgroup::
[2025-04-01T06:23:08.857+0000] {warnings.py:109} WARNING - /opt/***/dags/Entrenamiento_mode.py:64: UserWarning: pandas only supports SQLAlchemy connectable (engine/connection) or database string URI or sqlite3 DBAPI2 connection. Other DBAPI2 objects are not tested. Please consider using SQLAlchemy.
  df = pd.read_sql(query, conn)

[2025-04-01T06:23:09.201+0000] {logging_mixin.py:190} WARNING - 2025/04/01 06:23:09 INFO mlflow.tracking.fluent: Experiment with name 'mlflow_tracking_examples' does not exist. Creating a new experiment.
[2025-04-01T06:23:12.707+0000] {logging_mixin.py:190} WARNING - 2025/04/01 06:23:12 WARNING mlflow.utils.git_utils: Failed to import Git (the Git executable is probably not on your PATH), so Git SHA is not available. Error: Failed to initialize: Bad git executable.
The git executable must be specified in one of the following ways:
    - be included in your $PATH
    - be set via $GIT_PYTHON_GIT_EXECUTABLE
    - explicitly set via git.refresh(<full-path-to-git-executable>)

All git commands will error until this is rectified.

This initial message can be silenced or aggravated in the future by setting the
$GIT_PYTHON_REFRESH environment variable. Use one of the following values:
    - quiet|q|silence|s|silent|none|n|0: for no message or exception
    - warn|w|warning|log|l|1: for a warning message (logging level CRITICAL, displayed by default)
    - error|e|exception|raise|r|2: for a raised exception

Example:
    export GIT_PYTHON_REFRESH=quiet
[2025-04-01T06:23:12.811+0000] {logging_mixin.py:190} WARNING - 2025/04/01 06:23:12 WARNING mlflow.utils: Truncated the value of the key `estimator`. Truncated value: `Pipeline(steps=[('column_trans',
                 ColumnTransformer(remainder='passthrough',
                                   transformers=[('onehotencoder',
                                                  OneHotEncoder(handle_unknown='ignore'),
                                                  ['Wilderness_Area',
                                                   'Soil_Type'])])),
                ('scaler', StandardScaler(with_mean=False)),
                ('RandomForestClassifier', Rand...`
[2025-04-01T06:23:12.827+0000] {logging_and_warnings.py:72} WARNING - /home/***/.local/lib/python3.8/site-packages/joblib/parallel.py:1359: UserWarning: Loky-backed parallel loops cannot be called in a multiprocessing, setting n_jobs=1
  n_jobs = self._backend.configure(n_jobs=self.n_jobs, parallel=self,

[2025-04-01T06:23:12.843+0000] {logging_and_warnings.py:72} WARNING - /home/***/.local/lib/python3.8/site-packages/sklearn/model_selection/_split.py:676: UserWarning: The least populated class in y has only 3 members, which is less than n_splits=5.
  warnings.warn(

[2025-04-01T06:23:15.251+0000] {logging_and_warnings.py:72} WARNING - /home/***/.local/lib/python3.8/site-packages/sklearn/metrics/_classification.py:1318: UndefinedMetricWarning: Precision is ill-defined and being set to 0.0 in labels with no predicted samples. Use `zero_division` parameter to control this behavior.
  _warn_prf(average, modifier, msg_start, len(result))

[2025-04-01T06:23:16.959+0000] {font_manager.py:1547} INFO - generated new fontManager
[2025-04-01T06:23:19.952+0000] {credentials.py:1147} INFO - Found credentials in environment variables.
[2025-04-01T06:23:21.138+0000] {logging_mixin.py:190} WARNING - 2025/04/01 06:23:21 WARNING mlflow.utils.autologging_utils: MLflow autologging encountered a warning: "/home/***/.local/lib/python3.8/site-packages/mlflow/models/signature.py:137: UserWarning: Hint: Inferred schema contains integer column(s). Integer columns in Python cannot represent missing values. If your input data contains missing values at inference time, it will be encoded as floats and will cause a schema enforcement error. The best way to avoid this problem is to infer the model schema based on a realistic data sample (training dataset) that includes missing values. Alternatively, you can declare integer columns as doubles (float64) whenever these columns may have missing values. See `Handling Integers With Missing Values <https://www.mlflow.org/docs/latest/models.html#handling-integers-with-missing-values>`_ for more details."
[2025-04-01T06:23:33.083+0000] {logging_mixin.py:190} WARNING - Successfully registered model 'modelo1'.
[2025-04-01T06:23:33.212+0000] {logging_mixin.py:190} WARNING - 2025/04/01 06:23:33 INFO mlflow.tracking._model_registry.client: Waiting up to 300 seconds for model version to finish creation. Model name: modelo1, version 1
[2025-04-01T06:23:33.215+0000] {logging_mixin.py:190} WARNING - Created version '1' of model 'modelo1'.
[2025-04-01T06:23:41.844+0000] {logging_mixin.py:190} WARNING - 2025/04/01 06:23:41 INFO mlflow.sklearn.utils: Logging the 5 best runs, 3 runs will be omitted.
[2025-04-01T06:23:43.191+0000] {python.py:240} INFO - Done. Returned value was: 0
[2025-04-01T06:23:43.258+0000] {taskinstance.py:341} INFO - ::group::Post task execution logs
[2025-04-01T06:23:43.259+0000] {taskinstance.py:353} INFO - Marking task as SUCCESS. dag_id=4-Entrenamiento_model, task_id=entrenar_modelo, run_id=scheduled__2025-03-31T00:00:00+00:00, execution_date=20250331T000000, start_date=20250401T062308, end_date=20250401T062343
[2025-04-01T06:23:43.526+0000] {local_task_job_runner.py:266} INFO - Task exited with return code 0
[2025-04-01T06:23:43.593+0000] {taskinstance.py:3901} INFO - 0 downstream tasks scheduled from follow-on schedule check
[2025-04-01T06:23:43.598+0000] {local_task_job_runner.py:245} INFO - ::endgroup::
[2025-04-01T06:55:50.918+0000] {local_task_job_runner.py:123} INFO - ::group::Pre task execution logs
[2025-04-01T06:55:50.976+0000] {taskinstance.py:2614} INFO - Dependencies all met for dep_context=non-requeueable deps ti=<TaskInstance: 4-Entrenamiento_model.entrenar_modelo scheduled__2025-03-31T00:00:00+00:00 [queued]>
[2025-04-01T06:55:50.996+0000] {taskinstance.py:2614} INFO - Dependencies all met for dep_context=requeueable deps ti=<TaskInstance: 4-Entrenamiento_model.entrenar_modelo scheduled__2025-03-31T00:00:00+00:00 [queued]>
[2025-04-01T06:55:50.996+0000] {taskinstance.py:2867} INFO - Starting attempt 1 of 2
[2025-04-01T06:55:51.015+0000] {taskinstance.py:2890} INFO - Executing <Task(PythonOperator): entrenar_modelo> on 2025-03-31 00:00:00+00:00
[2025-04-01T06:55:51.050+0000] {standard_task_runner.py:72} INFO - Started process 166 to run task
[2025-04-01T06:55:51.067+0000] {standard_task_runner.py:104} INFO - Running: ['***', 'tasks', 'run', '4-Entrenamiento_model', 'entrenar_modelo', 'scheduled__2025-03-31T00:00:00+00:00', '--job-id', '6', '--raw', '--subdir', 'DAGS_FOLDER/Entrenamiento_mode.py', '--cfg-path', '/tmp/tmpagus998x']
[2025-04-01T06:55:51.073+0000] {standard_task_runner.py:105} INFO - Job 6: Subtask entrenar_modelo
[2025-04-01T06:55:51.238+0000] {task_command.py:467} INFO - Running <TaskInstance: 4-Entrenamiento_model.entrenar_modelo scheduled__2025-03-31T00:00:00+00:00 [running]> on host fbd57094de13
[2025-04-01T06:55:51.471+0000] {taskinstance.py:3134} INFO - Exporting env vars: AIRFLOW_CTX_DAG_OWNER='***' AIRFLOW_CTX_DAG_ID='4-Entrenamiento_model' AIRFLOW_CTX_TASK_ID='entrenar_modelo' AIRFLOW_CTX_EXECUTION_DATE='2025-03-31T00:00:00+00:00' AIRFLOW_CTX_TRY_NUMBER='1' AIRFLOW_CTX_DAG_RUN_ID='scheduled__2025-03-31T00:00:00+00:00'
[2025-04-01T06:55:51.473+0000] {taskinstance.py:732} INFO - ::endgroup::
[2025-04-01T06:55:51.542+0000] {warnings.py:109} WARNING - /opt/***/dags/Entrenamiento_mode.py:64: UserWarning: pandas only supports SQLAlchemy connectable (engine/connection) or database string URI or sqlite3 DBAPI2 connection. Other DBAPI2 objects are not tested. Please consider using SQLAlchemy.
  df = pd.read_sql(query, conn)

[2025-04-01T06:55:51.924+0000] {logging_mixin.py:190} WARNING - 2025/04/01 06:55:51 INFO mlflow.tracking.fluent: Experiment with name 'mlflow_tracking_examples' does not exist. Creating a new experiment.
[2025-04-01T06:55:54.370+0000] {logging_mixin.py:190} WARNING - 2025/04/01 06:55:54 WARNING mlflow.utils.git_utils: Failed to import Git (the Git executable is probably not on your PATH), so Git SHA is not available. Error: Failed to initialize: Bad git executable.
The git executable must be specified in one of the following ways:
    - be included in your $PATH
    - be set via $GIT_PYTHON_GIT_EXECUTABLE
    - explicitly set via git.refresh(<full-path-to-git-executable>)

All git commands will error until this is rectified.

This initial message can be silenced or aggravated in the future by setting the
$GIT_PYTHON_REFRESH environment variable. Use one of the following values:
    - quiet|q|silence|s|silent|none|n|0: for no message or exception
    - warn|w|warning|log|l|1: for a warning message (logging level CRITICAL, displayed by default)
    - error|e|exception|raise|r|2: for a raised exception

Example:
    export GIT_PYTHON_REFRESH=quiet
[2025-04-01T06:55:54.680+0000] {logging_mixin.py:190} WARNING - 2025/04/01 06:55:54 WARNING mlflow.utils: Truncated the value of the key `estimator`. Truncated value: `Pipeline(steps=[('column_trans',
                 ColumnTransformer(remainder='passthrough',
                                   transformers=[('onehotencoder',
                                                  OneHotEncoder(handle_unknown='ignore'),
                                                  ['Wilderness_Area',
                                                   'Soil_Type'])])),
                ('scaler', StandardScaler(with_mean=False)),
                ('RandomForestClassifier', Rand...`
[2025-04-01T06:55:54.691+0000] {logging_and_warnings.py:72} WARNING - /home/***/.local/lib/python3.8/site-packages/joblib/parallel.py:1359: UserWarning: Loky-backed parallel loops cannot be called in a multiprocessing, setting n_jobs=1
  n_jobs = self._backend.configure(n_jobs=self.n_jobs, parallel=self,

[2025-04-01T06:55:54.704+0000] {logging_and_warnings.py:72} WARNING - /home/***/.local/lib/python3.8/site-packages/sklearn/model_selection/_split.py:676: UserWarning: The least populated class in y has only 4 members, which is less than n_splits=5.
  warnings.warn(

[2025-04-01T06:55:58.217+0000] {font_manager.py:1547} INFO - generated new fontManager
[2025-04-01T06:55:59.950+0000] {credentials.py:1147} INFO - Found credentials in environment variables.
[2025-04-01T06:56:01.061+0000] {logging_mixin.py:190} WARNING - 2025/04/01 06:56:01 WARNING mlflow.utils.autologging_utils: MLflow autologging encountered a warning: "/home/***/.local/lib/python3.8/site-packages/mlflow/models/signature.py:137: UserWarning: Hint: Inferred schema contains integer column(s). Integer columns in Python cannot represent missing values. If your input data contains missing values at inference time, it will be encoded as floats and will cause a schema enforcement error. The best way to avoid this problem is to infer the model schema based on a realistic data sample (training dataset) that includes missing values. Alternatively, you can declare integer columns as doubles (float64) whenever these columns may have missing values. See `Handling Integers With Missing Values <https://www.mlflow.org/docs/latest/models.html#handling-integers-with-missing-values>`_ for more details."
[2025-04-01T06:56:15.607+0000] {logging_mixin.py:190} WARNING - Successfully registered model 'modelo1'.
[2025-04-01T06:56:15.899+0000] {logging_mixin.py:190} WARNING - 2025/04/01 06:56:15 INFO mlflow.tracking._model_registry.client: Waiting up to 300 seconds for model version to finish creation. Model name: modelo1, version 1
[2025-04-01T06:56:15.900+0000] {logging_mixin.py:190} WARNING - Created version '1' of model 'modelo1'.
[2025-04-01T06:56:21.415+0000] {logging_mixin.py:190} WARNING - 2025/04/01 06:56:21 INFO mlflow.sklearn.utils: Logging the 5 best runs, 3 runs will be omitted.
[2025-04-01T06:56:22.128+0000] {python.py:240} INFO - Done. Returned value was: 0
[2025-04-01T06:56:22.201+0000] {taskinstance.py:341} INFO - ::group::Post task execution logs
[2025-04-01T06:56:22.201+0000] {taskinstance.py:353} INFO - Marking task as SUCCESS. dag_id=4-Entrenamiento_model, task_id=entrenar_modelo, run_id=scheduled__2025-03-31T00:00:00+00:00, execution_date=20250331T000000, start_date=20250401T065550, end_date=20250401T065622
[2025-04-01T06:56:22.349+0000] {local_task_job_runner.py:266} INFO - Task exited with return code 0
[2025-04-01T06:56:22.381+0000] {taskinstance.py:3901} INFO - 0 downstream tasks scheduled from follow-on schedule check
[2025-04-01T06:56:22.384+0000] {local_task_job_runner.py:245} INFO - ::endgroup::
[2025-04-01T17:07:31.154+0000] {local_task_job_runner.py:123} INFO - ::group::Pre task execution logs
[2025-04-01T17:07:31.247+0000] {taskinstance.py:2614} INFO - Dependencies all met for dep_context=non-requeueable deps ti=<TaskInstance: 4-Entrenamiento_model.entrenar_modelo scheduled__2025-03-31T00:00:00+00:00 [queued]>
[2025-04-01T17:07:31.295+0000] {taskinstance.py:2614} INFO - Dependencies all met for dep_context=requeueable deps ti=<TaskInstance: 4-Entrenamiento_model.entrenar_modelo scheduled__2025-03-31T00:00:00+00:00 [queued]>
[2025-04-01T17:07:31.296+0000] {taskinstance.py:2867} INFO - Starting attempt 1 of 2
[2025-04-01T17:07:31.369+0000] {taskinstance.py:2890} INFO - Executing <Task(PythonOperator): entrenar_modelo> on 2025-03-31 00:00:00+00:00
[2025-04-01T17:07:31.469+0000] {standard_task_runner.py:72} INFO - Started process 437 to run task
[2025-04-01T17:07:31.525+0000] {standard_task_runner.py:104} INFO - Running: ['***', 'tasks', 'run', '4-Entrenamiento_model', 'entrenar_modelo', 'scheduled__2025-03-31T00:00:00+00:00', '--job-id', '10', '--raw', '--subdir', 'DAGS_FOLDER/Entrenamiento_mode.py', '--cfg-path', '/tmp/tmpdcln2a4d']
[2025-04-01T17:07:31.567+0000] {standard_task_runner.py:105} INFO - Job 10: Subtask entrenar_modelo
[2025-04-01T17:07:32.150+0000] {task_command.py:467} INFO - Running <TaskInstance: 4-Entrenamiento_model.entrenar_modelo scheduled__2025-03-31T00:00:00+00:00 [running]> on host 56b31014e3cf
[2025-04-01T17:07:32.810+0000] {taskinstance.py:3134} INFO - Exporting env vars: AIRFLOW_CTX_DAG_OWNER='***' AIRFLOW_CTX_DAG_ID='4-Entrenamiento_model' AIRFLOW_CTX_TASK_ID='entrenar_modelo' AIRFLOW_CTX_EXECUTION_DATE='2025-03-31T00:00:00+00:00' AIRFLOW_CTX_TRY_NUMBER='1' AIRFLOW_CTX_DAG_RUN_ID='scheduled__2025-03-31T00:00:00+00:00'
[2025-04-01T17:07:32.817+0000] {taskinstance.py:732} INFO - ::endgroup::
[2025-04-01T17:07:32.920+0000] {warnings.py:109} WARNING - /opt/***/dags/Entrenamiento_mode.py:64: UserWarning: pandas only supports SQLAlchemy connectable (engine/connection) or database string URI or sqlite3 DBAPI2 connection. Other DBAPI2 objects are not tested. Please consider using SQLAlchemy.
  df = pd.read_sql(query, conn)

[2025-04-01T17:07:34.840+0000] {logging_mixin.py:190} WARNING - 2025/04/01 17:07:34 WARNING mlflow.utils.git_utils: Failed to import Git (the Git executable is probably not on your PATH), so Git SHA is not available. Error: Failed to initialize: Bad git executable.
The git executable must be specified in one of the following ways:
    - be included in your $PATH
    - be set via $GIT_PYTHON_GIT_EXECUTABLE
    - explicitly set via git.refresh(<full-path-to-git-executable>)

All git commands will error until this is rectified.

This initial message can be silenced or aggravated in the future by setting the
$GIT_PYTHON_REFRESH environment variable. Use one of the following values:
    - quiet|q|silence|s|silent|none|n|0: for no message or exception
    - warn|w|warning|log|l|1: for a warning message (logging level CRITICAL, displayed by default)
    - error|e|exception|raise|r|2: for a raised exception

Example:
    export GIT_PYTHON_REFRESH=quiet
[2025-04-01T17:07:35.046+0000] {logging_mixin.py:190} WARNING - 2025/04/01 17:07:35 WARNING mlflow.utils: Truncated the value of the key `estimator`. Truncated value: `Pipeline(steps=[('column_trans',
                 ColumnTransformer(remainder='passthrough',
                                   transformers=[('onehotencoder',
                                                  OneHotEncoder(handle_unknown='ignore'),
                                                  ['Wilderness_Area',
                                                   'Soil_Type'])])),
                ('scaler', StandardScaler(with_mean=False)),
                ('RandomForestClassifier', Rand...`
[2025-04-01T17:07:35.151+0000] {logging_and_warnings.py:72} WARNING - /home/***/.local/lib/python3.8/site-packages/joblib/parallel.py:1359: UserWarning: Loky-backed parallel loops cannot be called in a multiprocessing, setting n_jobs=1
  n_jobs = self._backend.configure(n_jobs=self.n_jobs, parallel=self,

[2025-04-01T17:07:41.101+0000] {font_manager.py:1547} INFO - generated new fontManager
[2025-04-01T17:07:44.274+0000] {credentials.py:1147} INFO - Found credentials in environment variables.
[2025-04-01T17:07:46.183+0000] {logging_mixin.py:190} WARNING - 2025/04/01 17:07:46 WARNING mlflow.utils.autologging_utils: Encountered unexpected error during sklearn autologging: Failed to upload /tmp/tmp7at8xraa/training_confusion_matrix.png to mlflows3/artifacts/1/db1b6603808246feb85ec284e105f9d6/artifacts/training_confusion_matrix.png: An error occurred (NoSuchBucket) when calling the PutObject operation: The specified bucket does not exist
[2025-04-01T17:07:46.255+0000] {python.py:240} INFO - Done. Returned value was: 0
[2025-04-01T17:07:46.377+0000] {taskinstance.py:341} INFO - ::group::Post task execution logs
[2025-04-01T17:07:46.378+0000] {taskinstance.py:353} INFO - Marking task as SUCCESS. dag_id=4-Entrenamiento_model, task_id=entrenar_modelo, run_id=scheduled__2025-03-31T00:00:00+00:00, execution_date=20250331T000000, start_date=20250401T170731, end_date=20250401T170746
[2025-04-01T17:07:46.675+0000] {local_task_job_runner.py:266} INFO - Task exited with return code 0
[2025-04-01T17:07:46.760+0000] {taskinstance.py:3901} INFO - 0 downstream tasks scheduled from follow-on schedule check
[2025-04-01T17:07:46.764+0000] {local_task_job_runner.py:245} INFO - ::endgroup::
[2025-04-01T18:03:48.416+0000] {local_task_job_runner.py:123} INFO - ::group::Pre task execution logs
[2025-04-01T18:03:48.478+0000] {taskinstance.py:2614} INFO - Dependencies all met for dep_context=non-requeueable deps ti=<TaskInstance: 4-Entrenamiento_model.entrenar_modelo scheduled__2025-03-31T00:00:00+00:00 [queued]>
[2025-04-01T18:03:48.519+0000] {taskinstance.py:2614} INFO - Dependencies all met for dep_context=requeueable deps ti=<TaskInstance: 4-Entrenamiento_model.entrenar_modelo scheduled__2025-03-31T00:00:00+00:00 [queued]>
[2025-04-01T18:03:48.519+0000] {taskinstance.py:2867} INFO - Starting attempt 1 of 2
[2025-04-01T18:03:48.562+0000] {taskinstance.py:2890} INFO - Executing <Task(PythonOperator): entrenar_modelo> on 2025-03-31 00:00:00+00:00
[2025-04-01T18:03:48.612+0000] {standard_task_runner.py:72} INFO - Started process 225 to run task
[2025-04-01T18:03:48.665+0000] {standard_task_runner.py:104} INFO - Running: ['***', 'tasks', 'run', '4-Entrenamiento_model', 'entrenar_modelo', 'scheduled__2025-03-31T00:00:00+00:00', '--job-id', '6', '--raw', '--subdir', 'DAGS_FOLDER/Entrenamiento_mode.py', '--cfg-path', '/tmp/tmpgxerepoo']
[2025-04-01T18:03:48.686+0000] {standard_task_runner.py:105} INFO - Job 6: Subtask entrenar_modelo
[2025-04-01T18:03:48.954+0000] {task_command.py:467} INFO - Running <TaskInstance: 4-Entrenamiento_model.entrenar_modelo scheduled__2025-03-31T00:00:00+00:00 [running]> on host 111d26a6d12f
[2025-04-01T18:03:49.399+0000] {taskinstance.py:3134} INFO - Exporting env vars: AIRFLOW_CTX_DAG_OWNER='***' AIRFLOW_CTX_DAG_ID='4-Entrenamiento_model' AIRFLOW_CTX_TASK_ID='entrenar_modelo' AIRFLOW_CTX_EXECUTION_DATE='2025-03-31T00:00:00+00:00' AIRFLOW_CTX_TRY_NUMBER='1' AIRFLOW_CTX_DAG_RUN_ID='scheduled__2025-03-31T00:00:00+00:00'
[2025-04-01T18:03:49.419+0000] {taskinstance.py:732} INFO - ::endgroup::
[2025-04-01T18:03:49.545+0000] {warnings.py:109} WARNING - /opt/***/dags/Entrenamiento_mode.py:64: UserWarning: pandas only supports SQLAlchemy connectable (engine/connection) or database string URI or sqlite3 DBAPI2 connection. Other DBAPI2 objects are not tested. Please consider using SQLAlchemy.
  df = pd.read_sql(query, conn)

[2025-04-01T18:03:49.887+0000] {logging_mixin.py:190} WARNING - 2025/04/01 18:03:49 INFO mlflow.tracking.fluent: Experiment with name 'mlflow_tracking_examples' does not exist. Creating a new experiment.
[2025-04-01T18:03:53.951+0000] {logging_mixin.py:190} WARNING - 2025/04/01 18:03:53 WARNING mlflow.utils.git_utils: Failed to import Git (the Git executable is probably not on your PATH), so Git SHA is not available. Error: Failed to initialize: Bad git executable.
The git executable must be specified in one of the following ways:
    - be included in your $PATH
    - be set via $GIT_PYTHON_GIT_EXECUTABLE
    - explicitly set via git.refresh(<full-path-to-git-executable>)

All git commands will error until this is rectified.

This initial message can be silenced or aggravated in the future by setting the
$GIT_PYTHON_REFRESH environment variable. Use one of the following values:
    - quiet|q|silence|s|silent|none|n|0: for no message or exception
    - warn|w|warning|log|l|1: for a warning message (logging level CRITICAL, displayed by default)
    - error|e|exception|raise|r|2: for a raised exception

Example:
    export GIT_PYTHON_REFRESH=quiet
[2025-04-01T18:03:54.096+0000] {logging_mixin.py:190} WARNING - 2025/04/01 18:03:54 WARNING mlflow.utils: Truncated the value of the key `estimator`. Truncated value: `Pipeline(steps=[('column_trans',
                 ColumnTransformer(remainder='passthrough',
                                   transformers=[('onehotencoder',
                                                  OneHotEncoder(handle_unknown='ignore'),
                                                  ['Wilderness_Area',
                                                   'Soil_Type'])])),
                ('scaler', StandardScaler(with_mean=False)),
                ('RandomForestClassifier', Rand...`
[2025-04-01T18:03:54.126+0000] {logging_and_warnings.py:72} WARNING - /home/***/.local/lib/python3.8/site-packages/joblib/parallel.py:1359: UserWarning: Loky-backed parallel loops cannot be called in a multiprocessing, setting n_jobs=1
  n_jobs = self._backend.configure(n_jobs=self.n_jobs, parallel=self,

[2025-04-01T18:03:54.143+0000] {logging_and_warnings.py:72} WARNING - /home/***/.local/lib/python3.8/site-packages/sklearn/model_selection/_split.py:676: UserWarning: The least populated class in y has only 4 members, which is less than n_splits=5.
  warnings.warn(

[2025-04-01T18:03:58.627+0000] {font_manager.py:1547} INFO - generated new fontManager
[2025-04-01T18:04:01.831+0000] {credentials.py:1147} INFO - Found credentials in environment variables.
[2025-04-01T18:04:03.268+0000] {logging_mixin.py:190} WARNING - 2025/04/01 18:04:03 WARNING mlflow.utils.autologging_utils: MLflow autologging encountered a warning: "/home/***/.local/lib/python3.8/site-packages/mlflow/models/signature.py:137: UserWarning: Hint: Inferred schema contains integer column(s). Integer columns in Python cannot represent missing values. If your input data contains missing values at inference time, it will be encoded as floats and will cause a schema enforcement error. The best way to avoid this problem is to infer the model schema based on a realistic data sample (training dataset) that includes missing values. Alternatively, you can declare integer columns as doubles (float64) whenever these columns may have missing values. See `Handling Integers With Missing Values <https://www.mlflow.org/docs/latest/models.html#handling-integers-with-missing-values>`_ for more details."
[2025-04-01T18:04:55.880+0000] {job.py:229} INFO - Heartbeat recovered after 22.69 seconds
[2025-04-01T18:05:23.262+0000] {logging_mixin.py:190} WARNING - Registered model 'modelo1' already exists. Creating a new version of this model...
[2025-04-01T18:05:23.583+0000] {logging_mixin.py:190} WARNING - 2025/04/01 18:05:23 WARNING mlflow.utils.autologging_utils: Encountered unexpected error during sklearn autologging: BAD_REQUEST: This Session's transaction has been rolled back due to a previous exception during flush. To begin a new transaction with this Session, first issue Session.rollback(). Original exception was: (MySQLdb.IntegrityError) (1062, "Duplicate entry 'modelo1-1' for key 'model_versions.PRIMARY'")
[SQL: INSERT INTO model_versions (name, version, creation_time, last_updated_time, description, user_id, current_stage, source, run_id, run_link, status, status_message) VALUES (%s, %s, %s, %s, %s, %s, %s, %s, %s, %s, %s, %s)]
[parameters: ('modelo1', 1, 1743530723374, 1743530723374, '', None, 'None', 's3://mlflows3/artifacts/1/6816a9c2e13046b39294fc80d769fcb8/artifacts/model', '6816a9c2e13046b39294fc80d769fcb8', '', 'READY', None)]
(Background on this error at: https://sqlalche.me/e/14/gkpj) (Background on this error at: https://sqlalche.me/e/14/7s2a)
[2025-04-01T18:05:23.678+0000] {python.py:240} INFO - Done. Returned value was: 0
[2025-04-01T18:05:23.949+0000] {taskinstance.py:341} INFO - ::group::Post task execution logs
[2025-04-01T18:05:23.960+0000] {taskinstance.py:353} INFO - Marking task as SUCCESS. dag_id=4-Entrenamiento_model, task_id=entrenar_modelo, run_id=scheduled__2025-03-31T00:00:00+00:00, execution_date=20250331T000000, start_date=20250401T180348, end_date=20250401T180523
[2025-04-01T18:05:24.447+0000] {local_task_job_runner.py:266} INFO - Task exited with return code 0
[2025-04-01T18:05:24.524+0000] {taskinstance.py:3901} INFO - 0 downstream tasks scheduled from follow-on schedule check
[2025-04-01T18:05:24.533+0000] {local_task_job_runner.py:245} INFO - ::endgroup::
