[2025-03-31T23:17:12.484+0000] {local_task_job_runner.py:123} INFO - ::group::Pre task execution logs
[2025-03-31T23:17:12.551+0000] {taskinstance.py:2614} INFO - Dependencies all met for dep_context=non-requeueable deps ti=<TaskInstance: 4-Entrenamiento_model.entrenar_modelo manual__2025-03-31T23:17:02.838500+00:00 [queued]>
[2025-03-31T23:17:12.594+0000] {taskinstance.py:2614} INFO - Dependencies all met for dep_context=requeueable deps ti=<TaskInstance: 4-Entrenamiento_model.entrenar_modelo manual__2025-03-31T23:17:02.838500+00:00 [queued]>
[2025-03-31T23:17:12.595+0000] {taskinstance.py:2867} INFO - Starting attempt 1 of 2
[2025-03-31T23:17:12.675+0000] {taskinstance.py:2890} INFO - Executing <Task(PythonOperator): entrenar_modelo> on 2025-03-31 23:17:02.838500+00:00
[2025-03-31T23:17:12.755+0000] {standard_task_runner.py:72} INFO - Started process 133 to run task
[2025-03-31T23:17:12.802+0000] {standard_task_runner.py:104} INFO - Running: ['***', 'tasks', 'run', '4-Entrenamiento_model', 'entrenar_modelo', 'manual__2025-03-31T23:17:02.838500+00:00', '--job-id', '3', '--raw', '--subdir', 'DAGS_FOLDER/Entrenamiento_mode.py', '--cfg-path', '/tmp/tmptopg3ne9']
[2025-03-31T23:17:12.828+0000] {standard_task_runner.py:105} INFO - Job 3: Subtask entrenar_modelo
[2025-03-31T23:17:13.282+0000] {task_command.py:467} INFO - Running <TaskInstance: 4-Entrenamiento_model.entrenar_modelo manual__2025-03-31T23:17:02.838500+00:00 [running]> on host 45ab05f75c83
[2025-03-31T23:17:13.867+0000] {taskinstance.py:3134} INFO - Exporting env vars: AIRFLOW_CTX_DAG_OWNER='***' AIRFLOW_CTX_DAG_ID='4-Entrenamiento_model' AIRFLOW_CTX_TASK_ID='entrenar_modelo' AIRFLOW_CTX_EXECUTION_DATE='2025-03-31T23:17:02.838500+00:00' AIRFLOW_CTX_TRY_NUMBER='1' AIRFLOW_CTX_DAG_RUN_ID='manual__2025-03-31T23:17:02.838500+00:00'
[2025-03-31T23:17:13.881+0000] {taskinstance.py:732} INFO - ::endgroup::
[2025-03-31T23:17:14.223+0000] {warnings.py:109} WARNING - /opt/***/dags/Entrenamiento_mode.py:64: UserWarning: pandas only supports SQLAlchemy connectable (engine/connection) or database string URI or sqlite3 DBAPI2 connection. Other DBAPI2 objects are not tested. Please consider using SQLAlchemy.
  df = pd.read_sql(query, conn)

[2025-03-31T23:17:14.275+0000] {taskinstance.py:3313} ERROR - Task failed with exception
Traceback (most recent call last):
  File "/home/airflow/.local/lib/python3.8/site-packages/pandas/io/sql.py", line 2202, in execute
    cur.execute(sql, *args)
psycopg2.errors.UndefinedTable: relation "covertype" does not exist
LINE 1: SELECT * FROM covertype
                      ^


The above exception was the direct cause of the following exception:

Traceback (most recent call last):
  File "/home/airflow/.local/lib/python3.8/site-packages/airflow/models/taskinstance.py", line 768, in _execute_task
    result = _execute_callable(context=context, **execute_callable_kwargs)
  File "/home/airflow/.local/lib/python3.8/site-packages/airflow/models/taskinstance.py", line 734, in _execute_callable
    return ExecutionCallableRunner(
  File "/home/airflow/.local/lib/python3.8/site-packages/airflow/utils/operator_helpers.py", line 252, in run
    return self.func(*args, **kwargs)
  File "/home/airflow/.local/lib/python3.8/site-packages/airflow/models/baseoperator.py", line 424, in wrapper
    return func(self, *args, **kwargs)
  File "/home/airflow/.local/lib/python3.8/site-packages/airflow/operators/python.py", line 238, in execute
    return_value = self.execute_callable()
  File "/home/airflow/.local/lib/python3.8/site-packages/airflow/operators/python.py", line 256, in execute_callable
    return runner.run(*self.op_args, **self.op_kwargs)
  File "/home/airflow/.local/lib/python3.8/site-packages/airflow/utils/operator_helpers.py", line 252, in run
    return self.func(*args, **kwargs)
  File "/opt/airflow/dags/Entrenamiento_mode.py", line 73, in entrenar_modelo
    df_covertype = query_covertype()
  File "/opt/airflow/dags/Entrenamiento_mode.py", line 64, in query_covertype
    df = pd.read_sql(query, conn)
  File "/home/airflow/.local/lib/python3.8/site-packages/pandas/io/sql.py", line 635, in read_sql
    return pandas_sql.read_query(
  File "/home/airflow/.local/lib/python3.8/site-packages/pandas/io/sql.py", line 2266, in read_query
    cursor = self.execute(sql, params)
  File "/home/airflow/.local/lib/python3.8/site-packages/pandas/io/sql.py", line 2214, in execute
    raise ex from exc
pandas.errors.DatabaseError: Execution failed on sql 'SELECT * FROM covertype': relation "covertype" does not exist
LINE 1: SELECT * FROM covertype
                      ^

[2025-03-31T23:17:14.443+0000] {taskinstance.py:1226} INFO - Marking task as UP_FOR_RETRY. dag_id=4-Entrenamiento_model, task_id=entrenar_modelo, run_id=manual__2025-03-31T23:17:02.838500+00:00, execution_date=20250331T231702, start_date=20250331T231712, end_date=20250331T231714
[2025-03-31T23:17:14.780+0000] {taskinstance.py:341} INFO - ::group::Post task execution logs
[2025-03-31T23:17:14.781+0000] {standard_task_runner.py:124} ERROR - Failed to execute job 3 for task entrenar_modelo (Execution failed on sql 'SELECT * FROM covertype': relation "covertype" does not exist
LINE 1: SELECT * FROM covertype
                      ^
; 133)
Traceback (most recent call last):
  File "/home/airflow/.local/lib/python3.8/site-packages/pandas/io/sql.py", line 2202, in execute
    cur.execute(sql, *args)
psycopg2.errors.UndefinedTable: relation "covertype" does not exist
LINE 1: SELECT * FROM covertype
                      ^


The above exception was the direct cause of the following exception:

Traceback (most recent call last):
  File "/home/airflow/.local/lib/python3.8/site-packages/airflow/task/task_runner/standard_task_runner.py", line 117, in _start_by_fork
    ret = args.func(args, dag=self.dag)
  File "/home/airflow/.local/lib/python3.8/site-packages/airflow/cli/cli_config.py", line 49, in command
    return func(*args, **kwargs)
  File "/home/airflow/.local/lib/python3.8/site-packages/airflow/utils/cli.py", line 116, in wrapper
    return f(*args, **kwargs)
  File "/home/airflow/.local/lib/python3.8/site-packages/airflow/cli/commands/task_command.py", line 483, in task_run
    task_return_code = _run_task_by_selected_method(args, _dag, ti)
  File "/home/airflow/.local/lib/python3.8/site-packages/airflow/cli/commands/task_command.py", line 256, in _run_task_by_selected_method
    return _run_raw_task(args, ti)
  File "/home/airflow/.local/lib/python3.8/site-packages/airflow/cli/commands/task_command.py", line 341, in _run_raw_task
    return ti._run_raw_task(
  File "/home/airflow/.local/lib/python3.8/site-packages/airflow/utils/session.py", line 97, in wrapper
    return func(*args, session=session, **kwargs)
  File "/home/airflow/.local/lib/python3.8/site-packages/airflow/models/taskinstance.py", line 3006, in _run_raw_task
    return _run_raw_task(
  File "/home/airflow/.local/lib/python3.8/site-packages/airflow/models/taskinstance.py", line 274, in _run_raw_task
    TaskInstance._execute_task_with_callbacks(
  File "/home/airflow/.local/lib/python3.8/site-packages/airflow/models/taskinstance.py", line 3161, in _execute_task_with_callbacks
    result = self._execute_task(context, task_orig)
  File "/home/airflow/.local/lib/python3.8/site-packages/airflow/models/taskinstance.py", line 3185, in _execute_task
    return _execute_task(self, context, task_orig)
  File "/home/airflow/.local/lib/python3.8/site-packages/airflow/models/taskinstance.py", line 768, in _execute_task
    result = _execute_callable(context=context, **execute_callable_kwargs)
  File "/home/airflow/.local/lib/python3.8/site-packages/airflow/models/taskinstance.py", line 734, in _execute_callable
    return ExecutionCallableRunner(
  File "/home/airflow/.local/lib/python3.8/site-packages/airflow/utils/operator_helpers.py", line 252, in run
    return self.func(*args, **kwargs)
  File "/home/airflow/.local/lib/python3.8/site-packages/airflow/models/baseoperator.py", line 424, in wrapper
    return func(self, *args, **kwargs)
  File "/home/airflow/.local/lib/python3.8/site-packages/airflow/operators/python.py", line 238, in execute
    return_value = self.execute_callable()
  File "/home/airflow/.local/lib/python3.8/site-packages/airflow/operators/python.py", line 256, in execute_callable
    return runner.run(*self.op_args, **self.op_kwargs)
  File "/home/airflow/.local/lib/python3.8/site-packages/airflow/utils/operator_helpers.py", line 252, in run
    return self.func(*args, **kwargs)
  File "/opt/airflow/dags/Entrenamiento_mode.py", line 73, in entrenar_modelo
    df_covertype = query_covertype()
  File "/opt/airflow/dags/Entrenamiento_mode.py", line 64, in query_covertype
    df = pd.read_sql(query, conn)
  File "/home/airflow/.local/lib/python3.8/site-packages/pandas/io/sql.py", line 635, in read_sql
    return pandas_sql.read_query(
  File "/home/airflow/.local/lib/python3.8/site-packages/pandas/io/sql.py", line 2266, in read_query
    cursor = self.execute(sql, params)
  File "/home/airflow/.local/lib/python3.8/site-packages/pandas/io/sql.py", line 2214, in execute
    raise ex from exc
pandas.errors.DatabaseError: Execution failed on sql 'SELECT * FROM covertype': relation "covertype" does not exist
LINE 1: SELECT * FROM covertype
                      ^

[2025-03-31T23:17:14.943+0000] {local_task_job_runner.py:266} INFO - Task exited with return code 1
[2025-03-31T23:17:15.138+0000] {taskinstance.py:3901} INFO - 0 downstream tasks scheduled from follow-on schedule check
[2025-03-31T23:17:15.145+0000] {local_task_job_runner.py:245} INFO - ::endgroup::
