[2025-04-02T02:36:09.419+0000] {local_task_job_runner.py:123} INFO - ::group::Pre task execution logs
[2025-04-02T02:36:09.465+0000] {taskinstance.py:2614} INFO - Dependencies all met for dep_context=non-requeueable deps ti=<TaskInstance: 4-Entrenamiento_model.entrenar_modelo scheduled__2025-04-01T00:02:00+00:00 [queued]>
[2025-04-02T02:36:09.476+0000] {taskinstance.py:2614} INFO - Dependencies all met for dep_context=requeueable deps ti=<TaskInstance: 4-Entrenamiento_model.entrenar_modelo scheduled__2025-04-01T00:02:00+00:00 [queued]>
[2025-04-02T02:36:09.477+0000] {taskinstance.py:2867} INFO - Starting attempt 2 of 2
[2025-04-02T02:36:09.493+0000] {taskinstance.py:2890} INFO - Executing <Task(PythonOperator): entrenar_modelo> on 2025-04-01 00:02:00+00:00
[2025-04-02T02:36:09.517+0000] {standard_task_runner.py:72} INFO - Started process 182 to run task
[2025-04-02T02:36:09.527+0000] {standard_task_runner.py:104} INFO - Running: ['***', 'tasks', 'run', '4-Entrenamiento_model', 'entrenar_modelo', 'scheduled__2025-04-01T00:02:00+00:00', '--job-id', '9', '--raw', '--subdir', 'DAGS_FOLDER/Entrenamiento_mode.py', '--cfg-path', '/tmp/tmpe76avp0a']
[2025-04-02T02:36:09.533+0000] {standard_task_runner.py:105} INFO - Job 9: Subtask entrenar_modelo
[2025-04-02T02:36:09.636+0000] {task_command.py:467} INFO - Running <TaskInstance: 4-Entrenamiento_model.entrenar_modelo scheduled__2025-04-01T00:02:00+00:00 [running]> on host 66352f2efff5
[2025-04-02T02:36:09.918+0000] {taskinstance.py:3134} INFO - Exporting env vars: AIRFLOW_CTX_DAG_OWNER='***' AIRFLOW_CTX_DAG_ID='4-Entrenamiento_model' AIRFLOW_CTX_TASK_ID='entrenar_modelo' AIRFLOW_CTX_EXECUTION_DATE='2025-04-01T00:02:00+00:00' AIRFLOW_CTX_TRY_NUMBER='2' AIRFLOW_CTX_DAG_RUN_ID='scheduled__2025-04-01T00:02:00+00:00'
[2025-04-02T02:36:09.920+0000] {taskinstance.py:732} INFO - ::endgroup::
[2025-04-02T02:36:09.996+0000] {warnings.py:109} WARNING - /opt/***/dags/Entrenamiento_mode.py:64: UserWarning: pandas only supports SQLAlchemy connectable (engine/connection) or database string URI or sqlite3 DBAPI2 connection. Other DBAPI2 objects are not tested. Please consider using SQLAlchemy.
  df = pd.read_sql(query, conn)

[2025-04-02T02:36:10.304+0000] {logging_mixin.py:190} WARNING - 2025/04/02 02:36:10 INFO mlflow.tracking.fluent: Experiment with name 'mlflow_tracking_examples' does not exist. Creating a new experiment.
[2025-04-02T02:36:13.069+0000] {logging_mixin.py:190} WARNING - 2025/04/02 02:36:13 WARNING mlflow.utils.git_utils: Failed to import Git (the Git executable is probably not on your PATH), so Git SHA is not available. Error: Failed to initialize: Bad git executable.
The git executable must be specified in one of the following ways:
    - be included in your $PATH
    - be set via $GIT_PYTHON_GIT_EXECUTABLE
    - explicitly set via git.refresh(<full-path-to-git-executable>)

All git commands will error until this is rectified.

This initial message can be silenced or aggravated in the future by setting the
$GIT_PYTHON_REFRESH environment variable. Use one of the following values:
    - quiet|q|silence|s|silent|none|n|0: for no message or exception
    - warn|w|warning|log|l|1: for a warning message (logging level CRITICAL, displayed by default)
    - error|e|exception|raise|r|2: for a raised exception

Example:
    export GIT_PYTHON_REFRESH=quiet
[2025-04-02T02:36:13.825+0000] {logging_mixin.py:190} WARNING - 2025/04/02 02:36:13 WARNING mlflow.utils: Truncated the value of the key `estimator`. Truncated value: `Pipeline(steps=[('column_trans',
                 ColumnTransformer(remainder='passthrough',
                                   transformers=[('onehotencoder',
                                                  OneHotEncoder(handle_unknown='ignore'),
                                                  ['Wilderness_Area',
                                                   'Soil_Type'])])),
                ('scaler', StandardScaler(with_mean=False)),
                ('RandomForestClassifier', Rand...`
[2025-04-02T02:36:13.850+0000] {logging_and_warnings.py:72} WARNING - /home/***/.local/lib/python3.8/site-packages/joblib/parallel.py:1359: UserWarning: Loky-backed parallel loops cannot be called in a multiprocessing, setting n_jobs=1
  n_jobs = self._backend.configure(n_jobs=self.n_jobs, parallel=self,

[2025-04-02T02:36:13.859+0000] {logging_and_warnings.py:72} WARNING - /home/***/.local/lib/python3.8/site-packages/sklearn/model_selection/_split.py:676: UserWarning: The least populated class in y has only 3 members, which is less than n_splits=5.
  warnings.warn(

[2025-04-02T02:36:17.108+0000] {font_manager.py:1547} INFO - generated new fontManager
[2025-04-02T02:36:18.726+0000] {credentials.py:1147} INFO - Found credentials in environment variables.
[2025-04-02T02:36:19.574+0000] {logging_mixin.py:190} WARNING - 2025/04/02 02:36:19 WARNING mlflow.utils.autologging_utils: MLflow autologging encountered a warning: "/home/***/.local/lib/python3.8/site-packages/mlflow/models/signature.py:137: UserWarning: Hint: Inferred schema contains integer column(s). Integer columns in Python cannot represent missing values. If your input data contains missing values at inference time, it will be encoded as floats and will cause a schema enforcement error. The best way to avoid this problem is to infer the model schema based on a realistic data sample (training dataset) that includes missing values. Alternatively, you can declare integer columns as doubles (float64) whenever these columns may have missing values. See `Handling Integers With Missing Values <https://www.mlflow.org/docs/latest/models.html#handling-integers-with-missing-values>`_ for more details."
[2025-04-02T02:36:30.826+0000] {logging_mixin.py:190} WARNING - Successfully registered model 'modelo1'.
[2025-04-02T02:36:30.928+0000] {logging_mixin.py:190} WARNING - 2025/04/02 02:36:30 INFO mlflow.tracking._model_registry.client: Waiting up to 300 seconds for model version to finish creation. Model name: modelo1, version 1
[2025-04-02T02:36:30.928+0000] {logging_mixin.py:190} WARNING - Created version '1' of model 'modelo1'.
[2025-04-02T02:36:38.674+0000] {logging_mixin.py:190} WARNING - 2025/04/02 02:36:38 INFO mlflow.sklearn.utils: Logging the 5 best runs, 3 runs will be omitted.
[2025-04-02T02:36:39.666+0000] {python.py:240} INFO - Done. Returned value was: 0
[2025-04-02T02:36:39.729+0000] {taskinstance.py:341} INFO - ::group::Post task execution logs
[2025-04-02T02:36:39.730+0000] {taskinstance.py:353} INFO - Marking task as SUCCESS. dag_id=4-Entrenamiento_model, task_id=entrenar_modelo, run_id=scheduled__2025-04-01T00:02:00+00:00, execution_date=20250401T000200, start_date=20250402T023609, end_date=20250402T023639
[2025-04-02T02:36:39.882+0000] {local_task_job_runner.py:266} INFO - Task exited with return code 0
[2025-04-02T02:36:39.918+0000] {taskinstance.py:3901} INFO - 0 downstream tasks scheduled from follow-on schedule check
[2025-04-02T02:36:39.920+0000] {local_task_job_runner.py:245} INFO - ::endgroup::
