[2025-03-09T02:38:13.379+0000] {taskinstance.py:1125} INFO - Dependencies all met for dep_context=non-requeueable deps ti=<TaskInstance: preprocess_penguins_data.preprocess_data manual__2025-03-09T02:38:06.839184+00:00 [queued]>
[2025-03-09T02:38:13.384+0000] {taskinstance.py:1125} INFO - Dependencies all met for dep_context=requeueable deps ti=<TaskInstance: preprocess_penguins_data.preprocess_data manual__2025-03-09T02:38:06.839184+00:00 [queued]>
[2025-03-09T02:38:13.384+0000] {taskinstance.py:1331} INFO - Starting attempt 1 of 2
[2025-03-09T02:38:13.391+0000] {taskinstance.py:1350} INFO - Executing <Task(PythonOperator): preprocess_data> on 2025-03-09 02:38:06.839184+00:00
[2025-03-09T02:38:13.394+0000] {standard_task_runner.py:57} INFO - Started process 505 to run task
[2025-03-09T02:38:13.396+0000] {standard_task_runner.py:84} INFO - Running: ['***', 'tasks', 'run', 'preprocess_penguins_data', 'preprocess_data', 'manual__2025-03-09T02:38:06.839184+00:00', '--job-id', '16', '--raw', '--subdir', 'DAGS_FOLDER/Procesa_data.py', '--cfg-path', '/tmp/tmpex4ivy45']
[2025-03-09T02:38:13.397+0000] {standard_task_runner.py:85} INFO - Job 16: Subtask preprocess_data
[2025-03-09T02:38:13.425+0000] {task_command.py:410} INFO - Running <TaskInstance: preprocess_penguins_data.preprocess_data manual__2025-03-09T02:38:06.839184+00:00 [running]> on host ff47eccb62dd
[2025-03-09T02:38:13.530+0000] {taskinstance.py:1570} INFO - Exporting env vars: AIRFLOW_CTX_DAG_OWNER='***' AIRFLOW_CTX_DAG_ID='preprocess_penguins_data' AIRFLOW_CTX_TASK_ID='preprocess_data' AIRFLOW_CTX_EXECUTION_DATE='2025-03-09T02:38:06.839184+00:00' AIRFLOW_CTX_TRY_NUMBER='1' AIRFLOW_CTX_DAG_RUN_ID='manual__2025-03-09T02:38:06.839184+00:00'
[2025-03-09T02:38:13.530+0000] {taskinstance.py:1847} ERROR - Task failed with exception
Traceback (most recent call last):
  File "/home/airflow/.local/lib/python3.7/site-packages/airflow/operators/python.py", line 181, in execute
    return_value = self.execute_callable()
  File "/home/airflow/.local/lib/python3.7/site-packages/airflow/operators/python.py", line 198, in execute_callable
    return self.python_callable(*self.op_args, **self.op_kwargs)
  File "/opt/airflow/dags/Procesa_data.py", line 56, in preprocess_data
    X = df.drop(['species'], axis=1)
AttributeError: 'str' object has no attribute 'drop'
[2025-03-09T02:38:13.535+0000] {taskinstance.py:1373} INFO - Marking task as FAILED. dag_id=preprocess_penguins_data, task_id=preprocess_data, execution_date=20250309T023806, start_date=20250309T023813, end_date=20250309T023813
[2025-03-09T02:38:13.540+0000] {standard_task_runner.py:109} ERROR - Failed to execute job 16 for task preprocess_data ('str' object has no attribute 'drop'; 505)
[2025-03-09T02:38:13.567+0000] {local_task_job_runner.py:232} INFO - Task exited with return code 1
[2025-03-09T02:38:13.581+0000] {taskinstance.py:2674} INFO - 0 downstream tasks scheduled from follow-on schedule check
