[2025-03-09T00:21:43.954+0000] {taskinstance.py:1125} INFO - Dependencies all met for dep_context=non-requeueable deps ti=<TaskInstance: preprocess_penguins_data.save_processed_data manual__2025-03-09T00:21:40.673123+00:00 [queued]>
[2025-03-09T00:21:43.958+0000] {taskinstance.py:1125} INFO - Dependencies all met for dep_context=requeueable deps ti=<TaskInstance: preprocess_penguins_data.save_processed_data manual__2025-03-09T00:21:40.673123+00:00 [queued]>
[2025-03-09T00:21:43.958+0000] {taskinstance.py:1331} INFO - Starting attempt 1 of 2
[2025-03-09T00:21:43.967+0000] {taskinstance.py:1350} INFO - Executing <Task(PythonOperator): save_processed_data> on 2025-03-09 00:21:40.673123+00:00
[2025-03-09T00:21:43.970+0000] {standard_task_runner.py:57} INFO - Started process 453 to run task
[2025-03-09T00:21:43.973+0000] {standard_task_runner.py:84} INFO - Running: ['***', 'tasks', 'run', 'preprocess_penguins_data', 'save_processed_data', 'manual__2025-03-09T00:21:40.673123+00:00', '--job-id', '19', '--raw', '--subdir', 'DAGS_FOLDER/Procesa_data.py', '--cfg-path', '/tmp/tmptblta0sx']
[2025-03-09T00:21:43.974+0000] {standard_task_runner.py:85} INFO - Job 19: Subtask save_processed_data
[2025-03-09T00:21:44.009+0000] {task_command.py:410} INFO - Running <TaskInstance: preprocess_penguins_data.save_processed_data manual__2025-03-09T00:21:40.673123+00:00 [running]> on host de40e2ed39bc
[2025-03-09T00:21:44.062+0000] {taskinstance.py:1570} INFO - Exporting env vars: AIRFLOW_CTX_DAG_OWNER='***' AIRFLOW_CTX_DAG_ID='preprocess_penguins_data' AIRFLOW_CTX_TASK_ID='save_processed_data' AIRFLOW_CTX_EXECUTION_DATE='2025-03-09T00:21:40.673123+00:00' AIRFLOW_CTX_TRY_NUMBER='1' AIRFLOW_CTX_DAG_RUN_ID='manual__2025-03-09T00:21:40.673123+00:00'
[2025-03-09T00:21:44.089+0000] {taskinstance.py:1847} ERROR - Task failed with exception
Traceback (most recent call last):
  File "/home/airflow/.local/lib/python3.7/site-packages/airflow/operators/python.py", line 181, in execute
    return_value = self.execute_callable()
  File "/home/airflow/.local/lib/python3.7/site-packages/airflow/operators/python.py", line 198, in execute_callable
    return self.python_callable(*self.op_args, **self.op_kwargs)
  File "/opt/airflow/dags/Procesa_data.py", line 105, in save_processed_data
    'y_train': pd.read_json(ti.xcom_pull(task_ids='preprocess_data', key='y_train')),
  File "/home/airflow/.local/lib/python3.7/site-packages/pandas/util/_decorators.py", line 207, in wrapper
    return func(*args, **kwargs)
  File "/home/airflow/.local/lib/python3.7/site-packages/pandas/util/_decorators.py", line 311, in wrapper
    return func(*args, **kwargs)
  File "/home/airflow/.local/lib/python3.7/site-packages/pandas/io/json/_json.py", line 614, in read_json
    return json_reader.read()
  File "/home/airflow/.local/lib/python3.7/site-packages/pandas/io/json/_json.py", line 748, in read
    obj = self._get_object_parser(self.data)
  File "/home/airflow/.local/lib/python3.7/site-packages/pandas/io/json/_json.py", line 770, in _get_object_parser
    obj = FrameParser(json, **kwargs).parse()
  File "/home/airflow/.local/lib/python3.7/site-packages/pandas/io/json/_json.py", line 885, in parse
    self._parse_no_numpy()
  File "/home/airflow/.local/lib/python3.7/site-packages/pandas/io/json/_json.py", line 1140, in _parse_no_numpy
    loads(json, precise_float=self.precise_float), dtype=None
  File "/home/airflow/.local/lib/python3.7/site-packages/pandas/core/frame.py", line 614, in __init__
    mgr = dict_to_mgr(data, index, columns, dtype=dtype, copy=copy, typ=manager)
  File "/home/airflow/.local/lib/python3.7/site-packages/pandas/core/internals/construction.py", line 465, in dict_to_mgr
    arrays, data_names, index, columns, dtype=dtype, typ=typ, consolidate=copy
  File "/home/airflow/.local/lib/python3.7/site-packages/pandas/core/internals/construction.py", line 119, in arrays_to_mgr
    index = _extract_index(arrays)
  File "/home/airflow/.local/lib/python3.7/site-packages/pandas/core/internals/construction.py", line 625, in _extract_index
    raise ValueError("If using all scalar values, you must pass an index")
ValueError: If using all scalar values, you must pass an index
[2025-03-09T00:21:44.094+0000] {taskinstance.py:1373} INFO - Marking task as UP_FOR_RETRY. dag_id=preprocess_penguins_data, task_id=save_processed_data, execution_date=20250309T002140, start_date=20250309T002143, end_date=20250309T002144
[2025-03-09T00:21:44.100+0000] {standard_task_runner.py:109} ERROR - Failed to execute job 19 for task save_processed_data (If using all scalar values, you must pass an index; 453)
[2025-03-09T00:21:44.144+0000] {local_task_job_runner.py:232} INFO - Task exited with return code 1
[2025-03-09T00:21:44.157+0000] {taskinstance.py:2674} INFO - 0 downstream tasks scheduled from follow-on schedule check
